Workbook

Sheet 1ERO. BÁSICO
A1: REGISTRO DE ESTUDIANTES INSCRITOS AL CENTRO DE FORMACIÓN K'ARMEL JUYUP'
A2: AÑO ESCOLAR 2025- 1° Básico
H3: PAGO MENSUALIDAD - 2025
A4: N° | B4: Nombre | C4: Apellidos | D4: Fecha de nacimiento | E4: % Beca | F4: Encargado/a | G4: Tel. Encargado | H4: ENERO | I4: FEBRERO | J4: MARZO | K4: ABRIL | L4: MAYO | M4: JUNIO | N4: JULIO | O4: AGOSTO | P4: SEPTIEMBRE | Q4: OCTUBRE | R4: NOVIEMBRE | S4: DICIEMBRE | T4: TOTAL | U4: Entregado | V4: Entrega marzo | W4: Entrega 21 de abril | Y4: 45839 | AA4: 1 de septiembre
A5: 1 | B5: Álvarez de la Cruz | C5: Astrid Dayana | D5: 40909 | F5: Yesenia de la Cruz García | G5: 3909 2709 | H5: 50 | I5: 50 | J5: 50 | K5: 50 | L5: 50 | M5: 50 | N5: 50 | T5: =SUM(H5:S5) -> 350 | W5: 50 | Y5: 100 | AA5: 100
A6: 1 | B6: Amaya Pérez | C6: Ana Camila Suceth | D6: 40777 | E6: 0.25 | F6: Ingrid Aracely Zelada Chinchilla | G6: 5961 2899 | H6: 50 | I6: 50 | J6: 50 | K6: 50 | L6: 50 | M6: 50 | N6: 50 | O6: 50 | T6: =SUM(H6:S6) -> 400 | W6: 100 | X6: 50 | Y6: 50 | Z6: 100
A7: 1 | B7: Armis | C7: Ángel Manuel | D7: 40591 | F7: María Boch / Claudia Armis Boch (mamá) | G7: 3990 5979 (Abuela) 45381094 (Mamá) | L7: 50 | M7: 50 | N7: 50 | O7: 50 | P7: 50 | Q7: 50 | T7: =SUM(H7:S7) -> 300 | U7: 200 | W7: 300
A8: 1 | B8: Batres Echeverria | C8: Marco Antonio | D8: 40766 | F8: Jubitza Echeverría Contreras | G8: 5045 7969 | H8: 50 | I8: 50 | J8: 50 | K8: 50 | L8: 50 | M8: 50 | N8: 50 | O8: 50 | P8: 50 | Q8: 50 | T8: =SUM(H8:S8) -> 500 | V8: 100 | X8: 150 | Z8: 100 | AA8: 50
A9: 1 | B9: Benito Pérez | C9: Kiara Julissa Leilany | D9: 40528 | F9: Jezly Robersy Mirella Benito López | G9: 4006 3989 | H9: 50 | I9: 50 | J9: 50 | K9: 50 | L9: 50 | M9: 50 | N9: 50 | T9: =SUM(H9:S9) -> 350 | W9: 150 | AA9: 200
A10: 1 | B10: Bonilla | C10: Jhorgeysil Ayleen | D10: 41068 | E10: 0.5 | F10: Silvia Azucena Bonilla Vanegas | G10: 3913 4349 | H10: 50 | I10: 50 | J10: 50 | K10: 50 | L10: 50 | M10: 50 | N10: 50 | O10: 50 | P10: 50 | Q10: 50 | T10: =SUM(H10:S10) -> 500 | V10: 100 | X10: 50 | Y10: 50 | Z10: 200
A11: 1 | B11: Contreras Corea | C11: Alberth de Jesús | D11: 40791 | F11: Karla Corea | G11: 4742 4386 | H11: 50 | I11: 50 | J11: 50 | K11: 50 | L11: 50 | M11: 50 | N11: 50 | O11: 50 | T11: =SUM(H11:S11) -> 400 | V11: 100 | W11: 50 | X11: 100 | Y11: 50 | AA11: 100
A12: 1 | B12: Flores Soyoy | C12: Angie Delyanne | D12: 41048 | F12: Julissa Xiomara Soyoy Tuquer | G12: 3709 6020 | H12: 50 | I12: 50 | J12: 50 | K12: 50 | L12: 50 | M12: 50 | N12: 50 | O12: 50 | T12: =SUM(H12:S12) -> 400 | V12: =H11+I11 -> 100 | W12: 50 | X12: 50 | Y12: 50 | Z12: 50 | AA12: 50
A13: 1 | B13: Gómez Rodríguez | C13: Abi Michelle | D13: 41145 | F13: Marta Julia Rodríguez | G13: 5615 4185 | J13: 50 | K13: 50 | L13: 50 | M13: 50 | N13: 50 | O13: 50 | P13: 50 | Q13: 50 | T13: =SUM(H13:S13) -> 400 | U13: 100 | V13: 100 | W13: 100 | Z13: 100
A14: 1 | B14: González Ordoñez | C14: Prisly Adairiz | D14: 40624 | F14: Amalia Muñoz | G14: 5124 2275 | H14: 50 | I14: 50 | J14: 50 | K14: 50 | L14: 50 | M14: 50 | N14: 50 | O14: 50 | T14: =SUM(H14:S14) -> 400 | V14: 100 | W14: 50 | X14: 50 | Y14: 50 | Z14: 50 | AA14: 50
A15: 1 | B15: González Sí | C15: Hamilthon Esaú | D15: 40845 | F15: María Elvira Sí Tot | G15: 4358 6033 | H15: 50 | I15: 50 | J15: 50 | K15: 50 | L15: 50 | M15: 50 | N15: 50 | O15: 50 | T15: =SUM(H15:S15) -> 400 | W15: 200 | X15: 50 | Y15: 50 | Z15: 50 | AA15: 50
A16: 1 | B16: Ismalé Pérez | C16: Antoni Vinicio | D16: 39800 | F16: Sandra Pérez | G16: 5693 4232 | H16: 50 | I16: 50 | J16: 50 | K16: 50 | L16: 50 | M16: 50 | N16: 50 | O16: 50 | P16: 50 | Q16: 50 | T16: =SUM(H16:S16) -> 500 | V16: 400
A17: 1 | B17: Jiménez Soyoy | C17: Sharon Alejandra | D17: 40451 | E17: 50 | F17: María Fernanda Miranda Paredes | G17: 4144 6981 | H17: 50 | I17: 50 | J17: 50 | K17: 50 | L17: 50 | M17: 50 | T17: =SUM(H17:S17) -> 300 | Y17: 300
A18: 1 | B18: Juárez Escalante | C18: Lisandro Saúl | D18: 41011 | F18: Gumercinda Concepción Escalante Hernández | G18: 5699 3330 | I18: 50 | J18: 50 | K18: 50 | L18: 50 | M18: 50 | N18: 50 | O18: 50 | T18: =SUM(H18:S18) -> 350 | U18: 50 | V18: 100 | Y18: 100 | Z18: 100
A19: 1 | B19: Macario Vicente | C19: Rosa María | D19: 40763 | E19: 50 | F19: Ana Macario Vicente | G19: 5868 2459 | H19: 50 | I19: 50 | J19: 50 | K19: 50 | L19: 50 | T19: =SUM(H19:S19) -> 250 | V19: 100 | X19: 100
A20: 1 | B20: Mateo Sapón | C20: Tomás Santiago | D20: 41591 | F20: María Maricela Sapón Sulugüi | G20: 3296 5044 | H20: 50 | I20: 50 | J20: 50 | K20: 50 | L20: 50 | M20: 50 | N20: 50 | O20: 50 | P20: 50 | T20: =SUM(H20:S20) -> 450 | V20: 50 | X20: 100 | Z20: 100 | AA20: 100
A21: 1 | B21: Molina Case | C21: Jhoshua Gamaliel | D21: 40881 | F21: Jonny Gamaliel Molina Contreras | G21: 3591 1949 | H21: 50 | I21: 50 | T21: =SUM(H21:S21) -> 100
A22: 1 | B22: Montes Arreola | C22: Austin Daniel | D22: 41018 | F22: Paula Melissa Estrada Arreola | G22: 5932 1086 | H22: 50 | I22: 50 | J22: 50 | K22: 50 | L22: 50 | M22: 50 | N22: 50 | O22: 50 | P22: 50 | Q22: 50 | T22: =SUM(H22:S22) -> 500 | V22: 150 | Z22: 200
A23: 1 | B23: Natareno Toc | C23: Jeffrey Mateo | D23: 40784 | F23: Domingo Elizabeth Natareno | G23: 3589 1672 | H23: 50 | I23: 50 | J23: 50 | K23: 50 | L23: 50 | M23: 50 | N23: 50 | O23: 50 | T23: =SUM(H23:S23) -> 400 | V23: 50 | X23: 50 | AA23: 200
B24: Patzán Hernández | C24: Mario Martin | D24: 40595 | E24: 0.5 | F24: Mario Martín Patzán Ortiz | G24: 36921603 | H24: 50 | J24: 50 | K24: 50 | T24: =SUM(H24:S24) -> 150 | W24: 100
A25: 1 | B25: Rivas Velásquez | C25: Martina Fátima Saraí | D25: 40661 | F25: Reyna Josefina Velásquez Ríos | G25: 58335953 | H25: 50 | I25: 50 | J25: 50 | K25: 50 | L25: 50 | M25: 50 | T25: =SUM(H25:S25) -> 300 | V25: 100 | Y25: 150
A26: 1 | B26: Rodas Zurdo | C26: Diego Andreé | D26: 40992 | F26: Andrea Paola Zurdo Batz | G26: 3304 9629 | H26: 50 | I26: 50 | T26: =SUM(H26:S26) -> 100 | V26: 100
A27: 1 | B27: Romero Méndez | C27: Katherine Mariana | D27: 40645 | H27: 50 | I27: 50 | J27: 50 | K27: 50 | L27: 50 | M27: 50 | N27: 50 | O27: 50 | T27: =SUM(H27:S27) -> 400 | V27: 50 | W27: 50 | Y27: 100 | Z27: 50 | AA27: 50
A28: 1 | B28: Roquel Caniche | C28: Edwin David | D28: 40934 | F28: Reina Araceli Caniche Nicolás | G28: 5113 9210 | I28: 50 | J28: 50 | K28: 50 | L28: 50 | M28: 50 | N28: 50 | O28: 50 | T28: =SUM(H28:S28) -> 350 | U28: 50 | W28: 100 | X28: 100 | Z28: 100
A29: 1 | B29: Simón Peren | C29: Candy Fabiola Odeth | D29: 41491 | F29: Elvira Peren Otzoy | G29: 3622 3361 | I29: 50 | J29: 50 | K29: 50 | L29: 50 | M29: 50 | N29: 50 | O29: 50 | T29: =SUM(H29:S29) -> 350 | U29: 50 | V29: 50 | W29: 50 | X29: 50 | Y29: 50 | Z29: 50 | AA29: 50
A30: 1 | B30: Soc Grande | C30: Norman Isaac | D30: 40888 | F30: Beatriz Soc | G30: 4844 2237 | T30: =SUM(H30:S30) -> 0 | U30: 500
A31: 1 | B31: Váldez Urbina | C31: Jennyfer Ximena | D31: 40665 | E31: 0.5 | F31: Julia Virginia Urbina Váldez | G31: 36921477 | H31: 50 | I31: 50 | J31: 50 | K31: 50 | L31: 50 | M31: 50 | N31: 50 | O31: 50 | T31: =SUM(H31:S31) -> 400 | W31: 100 | Z31: 250 | AA31: 50
A32: 1 | B32: Morales Mazate | C32: Génesis Sarai | L32: 50 | M32: 50 | N32: 50 | Y32: 100 | AA32: 50
A33: =SUM(A5:A32) -> 27 | H33: =SUM(H5:H31) -> 1050 | I33: =SUM(I5:I31) -> 1150 | J33: =SUM(J5:J31) -> 1150 | K33: =SUM(K5:K31) -> 1150 | L33: =SUM(L5:L31) -> 1150 | M33: =SUM(M5:M31) -> 1100 | N33: =SUM(N5:N32) -> 1050 | O33: =SUM(O5:O31) -> 900 | P33: =SUM(P5:P31) -> 350 | Q33: =SUM(Q5:Q31) -> 300 | R33: =SUM(R5:R31) -> 0 | S33: =SUM(S5:S31) -> 0 | T33: =SUM(H33:S33) -> 9350 | U33: =SUM(U5:U31) -> 950 | V33: =SUM(V5:V31) -> 1750 | W33: =SUM(W5:W31) -> 1450 | X33: =SUM(X5:X31) -> 900 | Y33: =SUM(Y5:Y32) -> 1200 | Z33: =SUM(Z5:Z32) -> 1500 | AA33: =SUM(AA5:AA32) -> 1100

Sheet 2DO. BÁSICO
A2: REGISTRO DE ESTUDIANTES INSCRITOS AL CENTRO DE FORMACIÓN K'ARMEL JUYUP'
A3: AÑO ESCOLAR 2025- 2° Básico | H3: PAGO MENSUALIDAD - 2025
A4: N° | B4: Nombre | C4: Apellidos | D4: Fecha de nacimiento | E4: % Beca | F4: Encargado/a | G4: Tel. Encargado | H4: ENERO | I4: FEBRERO | J4: MARZO | K4: ABRIL | L4: MAYO | M4: JUNIO | N4: JULIO | O4: AGOSTO | P4: SEPTIEMBRE | Q4: OCTUBRE | R4: NOVIEMBRE | S4: DICIEMBRE | T4: TOTAL | U4: Entregado | V4: Entrega Marzo | W4: Entrega 21 de abril | Y4: 45839 | AA4: 1 de septiembre
A5: 1 | B5: Carrera Lobos | C5: Mia Scarlet Susana | D5: 40583 | E5: 25 | F5: Verónica Patricia Lobos | G5: 4221 5210 | H5: 50 | I5: 50 | J5: 50 | K5: 50 | L5: 50 | M5: 50 | N5: 50 | O5: 50 | P5: 50 | Q5: 50 | T5: =SUM(H5:S5) -> 500 | V5: 100 | Y5: 200
A6: 1 | B6: Chocoj Rodríguez | C6: Candy Mishelle | D6: 40738 | F6: Enma Edelmira Rodríguez Estrada | G6: 5693 9034 | H6: 50 | I6: 50 | J6: 50 | K6: 50 | L6: 50 | M6: 50 | N6: 50 | O6: 50 | P6: 50 | Q6: 50 | T6: =SUM(H6:S6) -> 500 | W6: 200 | AA6: 100
A7: 1 | B7: Contreras Corea | C7: Sharóm Solansh Gabriela | D7: 40366 | F7: Karla Corea | G7: 4742 4386 | H7: 50 | I7: 50 | J7: 50 | K7: 50 | L7: 50 | M7: 50 | N7: 50 | O7: 50 | T7: =SUM(H7:S7) -> 400 | W7: 150 | X7: 100 | Y7: 50 | AA7: 100
A8: 1 | B8: Fernández Raymundo | C8: Daniela Jimena | D8: 39569 | E8: 50 | F8: Juana Janeth Raymundo Pop | G8: 3010 0349 | T8: =SUM(H8:S8) -> 0
A9: 1 | B9: Fernández Reyes | C9: William Jesús | D9: 40458 | F9: Mayra Marilú Reyes Chilin | G9: 5965 0988 | T9: =SUM(H9:S9) -> 0
A10: 1 | B10: Gutiérrez Salazar | C10: Ligia Virginia | D10: 40509 | F10: Ana Mabely Salazar Flores | G10: 4939 5804 | H10: 50 | I10: 50 | J10: 50 | K10: 50 | L10: 50 | M10: 50 | N10: 50 | O10: 50 | T10: =SUM(H10:S10) -> 400 | V10: 100 | X10: 100 | Y10: 100
A11: 1 | B11: Hernández Mendoza | C11: Adam Carlos Enrique | D11: 39995 | E11: 0.25 | F11: Linda Ssusset Mendoza Medrano | G11: 3813 3938 | J11: 50 | K11: 50 | L11: 50 | M11: 50 | N11: 50 | O11: 50 | P11: 50 | Q11: 50 | T11: =SUM(J11:S11) -> 400 | U11: 100 | V11: 100 | X11: 100 | Z11: 100 | AA11: 100
A12: 1 | B12: Hernández Vargas | C12: Karely Nicole | D12: 40604 | F12: Nolvia Liseth Vargas Orellana | G12: 36127776 | H12: 50 | I12: 50 | J12: 50 | K12: 50 | L12: 50 | M12: 50 | N12: 50 | O12: 50 | T12: =SUM(H12:S12) -> 400 | W12: 150 | Z12: 150
A13: 1 | B13: Higueros Burrión | C13: Alexandra Anahí Yanet | D13: 39256 | E13: 50 | F13: Celia Yaneth Burrión León | G13: 59915415 | H13: 50 | M13: 50 | T13: =SUM(H13:S13) -> 100 | X13: 50
A14: 1 | B14: Marroquín Orantes | C14: Scarlett Dajane | D14: 40711 | F14: Gloria Mirna Orantes | G14: 50636279 | L14: 50 | M14: 50 | N14: 50 | O14: 50 | T14: =SUM(L14:S14) -> 200 | U14: 200 | Y14: 200
A15: 1 | B15: Martin Ajiatáz | C15: Melany Anahí | D15: 39345 | E15: 25 | F15: Debora Raquel Ajiatás Hernández | G15: 5855 9961 | H15: 50 | I15: 50 | J15: 50 | K15: 50 | L15: 50 | M15: 50 | T15: =SUM(H15:S15) -> 300 | Y15: 300
A16: 1 | B16: Meletz Carrera | C16: Kristen Nicol | D16: 40406 | F16: Evelin Marleni Carrera Cruz | G16: 4443 1110 | H16: 50 | I16: 50 | J16: 50 | K16: 50 | L16: 50 | M16: 50 | N16: 50 | O16: 50 | T16: =SUM(H16:S16) -> 400 | V16: 100 | X16: 100 | Z16: 100
A17: 1 | B17: Méndez Ijchajchal | C17: Jeremy Alexis | D17: 40693 | F17: Dolores Ijchajchal Gónzalez | G17: 45232828 | H17: 50 | I17: 50 | J17: 50 | K17: 50 | L17: 50 | M17: 50 | N17: 50 | O17: 50 | T17: =SUM(H17:S17) -> 400 | V17: 50 | W17: 50 | X17: 50 | Y17: 50 | Z17: 50 | AA17: 50
A18: 1 | B18: Méndez Jacobo | C18: Caterine Helizabeth | H18: 50 | I18: 50 | J18: 50 | K18: 50 | L18: 50 | M18: 50 | N18: 50 | O18: 50 | P18: 50 | T18: =SUM(H18:S18) -> 450 | Y18: 150 | AA18: 100
A19: 1 | B19: Morales Agustín | C19: Ilbia Rosalia | D19: 40478 | F19: Ilbia Rosal+ia Agustín Yol | G19: 3795 0050 | I19: 50 | J19: 50 | K19: 50 | L19: 50 | M19: 50 | N19: 50 | T19: =SUM(I19:S19) -> 300 | U19: 50 | V19: 100 | W19: 50 | Y19: 150
A20: 1 | B20: Morataya Patzán | C20: Estefany Paola | D20: 40718 | F20: María de los Ángeles Patzán | G20: 4295 7039 | H20: 50 | I20: 50 | J20: 50 | K20: 50 | L20: 50 | M20: 50 | T20: =SUM(H20:S20) -> 300 | W20: 100 | Z20: 100
A21: 1 | B21: Ordoñez Zurdo | C21: Pedro Josué | D21: 39855 | F21: Andrea Paola Zurdo Batz | G21: 3304 9620 (WhatsApp) 4844 0150 ( Llamadas) | H21: 50 | I21: 50 | J21: 50 | T21: =SUM(H21:S21) -> 150 | V21: 150
A22: 1 | B22: Ordoñez Zurdo | C22: Julio Alejandro Jeremiah | D22: 40004 | F22: Andrea Paola Zurdo Batz | G22: 3304 9620 (WhatsApp) 4844 0150 ( Llamadas) | H22: 50 | I22: 50 | J22: 50 | T22: =SUM(H22:S22) -> 150 | V22: 150
A23: 1 | B23: Ozuna Barillas | C23: Ghylaine Cristina | D23: 40269 | F23: Jessica Mariela Ozuna Barillas | G23: 49190774 | H23: 50 | I23: 50 | J23: 50 | K23: 50 | L23: 50 | M23: 50 | T23: =SUM(H23:S23) -> 300 | Z23: 300
A24: 1 | B24: Patzan Díaz | C24: Sherlin Esmeralda | D24: 40615 | F24: Nancy Maribel Díaz Rueda / Ana María Barrientos | G24: 50817240 33355710 | T24: =SUM(R24:S24) -> 0 | U24: 500
A25: 1 | B25: Rafael Baíl | C25: Damaris Anay | D25: 40753 | F25: Ofelia Baíl Gómez | G25: 4576 9306 | H25: 50 | I25: 50 | J25: 50 | K25: 50 | L25: 50 | M25: 50 | N25: 50 | O25: 50 | P25: 50 | T25: =SUM(H25:S25) -> 450 | V25: 100 | X25: 100 | AA25: 150
A26: 1 | B26: Rangel Foronda | C26: Jeferson Omar Israel | D26: 40287 | E26: 25 | F26: Glenda Patricia Foronda | G26: 5976 1035 | H26: 50 | I26: 50 | J26: 50 | K26: 50 | L26: 50 | M26: 50 | N26: 50 | O26: 50 | T26: =SUM(H26:S26) -> 400 | X26: 100 | Z26: 100
B27: Salalá Soyos | C27: Joselin Michelle | D27: 40479 | E27: 25 | F27: María Sandra Soyos Xocoxic | G27: 4574 4662 | T27: =SUM(H27:S27) -> 0
B28: Salalá Soyos | C28: Mildre Aracely | D28: 39670 | E28: 25 | F28: María Sandra Soyos Xocoxic | G28: 4574 4662 | T28: =SUM(H28:S28) -> 0
A29: 1 | B29: Solis Salguero | C29: Iñaki Lorenzo Antonio | D29: 40528 | E29: 50 | F29: Hilda Salguero | G29: 41859786 | J29: 50 | K29: 50 | L29: 50 | M29: 50 | N29: 50 | O29: 50 | T29: =SUM(J29:S29) -> 300 | U29: 100 | V29: 100 | W29: 200
A30: 1 | B30: Toledo Chiquitó | C30: Kristofer Augusto | D30: 39975 | F30: Aura Estela Chiquitó | G30: 3118 0246 | I30: 50 | J30: 50 | K30: 50 | L30: 50 | M30: 50 | N30: 50 | O30: 50 | T30: =SUM(I30:S30) -> 350 | U30: 50 | V30: 50 | X30: 100 | Z30: 50 | AA30: 100
A31: 1 | B31: Tzul Quiñónez | C31: Londy María | D31: 26-012009 | F31: María Nieves García | G31: 5182 6697 | J31: 50 | K31: 50 | L31: 50 | M31: 50 | N31: 50 | O31: 50 | P31: 50 | Q31: 50 | T31: =SUM(J31:S31) -> 400 | U31: 100 | V31: 100 | X31: 100 | Z31: 100
A32: 1 | B32: Yoque Domingo | C32: Erick Andrés | D32: 40253 | F32: Carolina Jasmin Yoque Domingo | G32: 3737 0430 | T32: =SUM(H32:S32) -> 0
A33: =SUM(A5:A32) -> 26 | H33: =SUM(H5:H32) -> 800 | I33: =SUM(I5:I32) -> 850 | J33: =SUM(J5:J32) -> 1000 | K33: =SUM(K5:K32) -> 900 | L33: =SUM(L5:L32) -> 950 | M33: =SUM(M5:M32) -> 1000 | N33: =SUM(N5:N32) -> 800 | O33: =SUM(O5:O32) -> 750 | ... AA33: =SUM(AA5:AA32) -> 700

Sheet 3ERO. BÁSICO
A2: REGISTRO DE ESTUDIANTES INSCRITOS AL CENTRO DE FORMACIÓN K'ARMEL JUYUP'
A3: AÑO ESCOLAR 2025 - 3° Básico | H3: PAGO MENSUALIDAD - 2025
A4: N° | B4: Nombre | C4: Apellidos | D4: Fecha de nacimiento | E4: % Beca | F4: Encargado/a | G4: Tel. Encargado | H4: ENERO | I4: FEBRERO | J4: MARZO | K4: ABRIL | L4: MAYO | M4: JUNIO | N4: JULIO | O4: AGOSTO | P4: SEPTIEMBRE | Q4: OCTUBRE | R4: NOVIEMBRE | S4: DICIEMBRE | T4: TOTAL | U4: Entregado | V4: Entrega Marzo | W4: Entrega 21 de abril | Y4: 45839 | AA4: 1 de septiembre
A5: 1 | B5: Chaman | C5: Jessica Paola | D5: 40002 | F5: Celia Chamán | G5: 47616125 | T5: =SUM(R5:S5) -> 0 | U5: 500
A6: 1 | B6: Figueroa Martínez | C6: Eddy Randolfo | D6: 40030 | F6: Mayra Ester Aguilar/Huberto Randolfo Figueroa Natareno | G6: 3191 2974 (Abuela) / 59003561 (Abuelo) | L6: 50 | M6: 50 | N6: 50 | O6: 50 | P6: 50 | Q6: 50 | T6: =SUM(L6:S6) -> 300 | U6: 200 | Y6: 300
A7: 1 | B7: Jocón Barillas | C7: Emily Julissa | D7: 40041 | F7: Andrea Betzabé Barillas Villanueva | G7: 4964 7451 | L7: 50 | M7: 50 | N7: 50 | O7: 50 | T7: =SUM(L7:S7) -> 200 | U7: 200 | Y7: 200
A8: 1 | B8: Mauricio López | C8: Wendy Johana | D8: 40329 | F8: Eva López | G8: 46345995 | H8: 50 | I8: 50 | J8: 50 | K8: 50 | L8: 50 | T8: =SUM(H8:S8) -> 250 | V8: 50 | W8: 50 | Y8: 50
A9: 1 | B9: Méndez Chávez | C9: Ángel Ricardo | D9: 39539 | F9: Juan Ramón Chavez Alvarado | G9: 4761 9083 | H9: 50 | I9: 50 | J9: 50 | K9: 50 | L9: 50 | M9: 50 | N9: 50 | T9: =SUM(H9:S9) -> 350 | V9: 100 | X9: 50 | Z9: 100
A10: 1 | B10: Molina Case | C10: Maryury Daniela | D10: 39997 | F10: Jubitza Ninnet Case | G10: 4105 8068/51100327 | H10: 50 | I10: 50 | J10: 50 | T10: =SUM(H10:S10) -> 150 | W10: 50
A11: 1 | B11: Ochoa Quisquina | C11: Angelin Daniela | D11: 40191 | E11: 50 | F11: Antonia Quisquina Locón | G11: 45913845 | T11: =SUM(H11:S11) -> 0
A12: 1 | B12: Ortíz Yax | C12: Axel Emanuel | D12: 40363 | E12: 50 | F12: Evelyn Marleni Yax | G12: 50121187 | H12: 50 | I12: 50 | J12: 50 | K12: 50 | L12: 50 | M12: 50 | N12: 50 | O12: 50 | P12: 50 | T12: =SUM(H12:S12) -> 450 | W12: 250 | Y12: 50 | Z12: 50 | AA12: 100
A13: 1 | B13: Patzán Morales | C13: Cristian Rodolfo | D13: 40373 | F13: Rudy Rodolfo Patzán Gómez | H13: 50 | I13: 50 | J13: 50 | K13: 50 | L13: 50 | M13: 50 | T13: =SUM(H13:S13) -> 300 | W13: 200 | Y13: 100
A14: 1 | B14: Peren Otzoy | C14: Randy Alexander | I14: 50 | J14: 50 | K14: 50 | L14: 50 | M14: 50 | N14: 50 | O14: 50 | T14: =SUM(I14:S14) -> 350 | U14: 50 | V14: 50 | W14: 50 | X14: 50 | Y14: 50 | Z14: 50 | AA14: 50
A15: 1 | B15: Quisquina Locon | C15: Axel Eduardo | D15: 39821 | E15: 50 | F15: Antonieta Quisquina Locón | G15: 45913845 | T15: =SUM(H15:S15) -> 0
A16: 1 | B16: Saban | C16: María Elizabeth de la Soledad | D16: 39754 | E16: 50 | F16: Victoria Sabán | G16: 4502 8704 | H16: 50 | I16: 50 | J16: 50 | K16: 50 | L16: 50 | M16: 50 | N16: 50 | O16: 50 | P16: 50 | Q16: 50 | T16: =SUM(H16:S16) -> 500 | Y16: 100 | AA16: 150
A17: 1 | B17: Santizo de León | C17: Wilson Alexander | D17: 39610 | H17: 50 | I17: 50 | J17: 50 | K17: 50 | L17: 50 | M17: 50 | N17: 50 | O17: 50 | T17: =SUM(H17:S17) -> 400 | V17: 100 | X17: 100 | AA17: 100
A18: 1 | B18: Sicay Pérez | C18: Mayda Nicol | F18: Fermina Pérez Pérez | G18: 3982 1733 | H18: 50 | I18: 50 | J18: 50 | K18: 50 | L18: 50 | T18: =SUM(H18:S18) -> 250 | V18: 50 | X18: 100
A19: 1 | B19: Subuyuj Morales | C19: Angelly Marleni Noemy | D19: 39963 | E19: 50 | F19: Ana Marleni Morales Castillo | G19: 43393260 | H19: 50 | I19: 50 | J19: 50 | K19: 50 | L19: 50 | M19: 50 | N19: 50 | T19: =SUM(H19:S19) -> 350 | V19: 100 | Y19: 50 | Z19: 50 | AA19: 50
A20: 1 | B20: Tiul Coc | C20: Jayra Baneza | D20: 39849 | F20: Hermelindo Tiul Coc | G20: 3044 4545 | H20: 50 | I20: 50 | J20: 50 | K20: 50 | L20: 50 | M20: 50 | N20: 50 | O20: 50 | T20: =SUM(H20:S20) -> 400 | V20: 50 | X20: 100 | Y20: 50 | Z20: 100
A21: 1 | B21: Váldez Urbina | C21: Jefersón Estiven | D21: 39724 | E21: 50 | F21: Julia Urbina | G21: 3692 1477 | H21: 50 | I21: 50 | J21: 50 | K21: 50 | L21: 50 | M21: 50 | N21: 50 | O21: 50 | T21: =SUM(H21:S21) -> 400 | W21: 100 | Z21: 250 | AA21: 50
A22: 1 | B22: Villagrán Mijangos | C22: Katheryn Amarylis | D22: 39826 | F22: Juan Carlois Villagrán | G22: 41343873 | I22: 50 | J22: 50 | K22: 50 | L22: 50 | M22: 50 | N22: 50 | T22: =SUM(I22:S22) -> 300 | U22: 50 | V22: 100 | Y22: 100
A23: =SUM(A5:A22) -> 18 | H23: =SUM(H5:H22) -> 550 | I23: =SUM(I5:I22) -> 650 | J23: =SUM(J5:J22) -> 650 | K23: =SUM(K5:K22) -> 600 | L23: =SUM(L5:L22) -> 700 | M23: =SUM(M5:M22) -> 600 | N23: =SUM(N5:N22) -> 550 | O23: =SUM(O5:O22) -> 400 | ... S23: =SUM(S5:S22) -> 0 | T23: =SUM(T5:T20) -> 4250 | U23: =SUM(U5:U22) -> 1000 | V23: =SUM(V5:V22) -> 600 | W23: =SUM(W5:W22) -> 700 | X23: =SUM(X5:X22) -> 400 | Y23: =SUM(Y5:Y22) -> 1050 | Z23: =SUM(Z5:Z22) -> 600 | AA23: =SUM(AA5:AA22) -> 500

Sheet 4TO. BACHILLERATO
A2: REGISTRO DE ESTUDIANTES INSCRITOS AL CENTRO DE FORMACIÓN K'ARMEL JUYUP'
A3: AÑO ESCOLAR 2025. 4° Bachillerato | H3: PAGO MENSUALIDAD - 2025
A4: N° | B4: Nombre | C4: Apellidos | D4: Fecha de nacimiento | E4: % Beca | F4: Encargado/a | G4: Tel. Encargado | H4: ENERO | I4: FEBRERO | J4: MARZO | K4: ABRIL | L4: MAYO | M4: JUNIO | N4: JULIO | O4: AGOSTO | P4: SEPTIEMBRE | Q4: OCTUBRE | R4: NOVIEMBRE | S4: DICIEMBRE | T4: TOTAL | U4: Entregado | V4: Entrega Marzo | W4: Entrega 21 de abril | Y4: 45839 | AA4: 1 de septiembre
A5: 1 | B5: Ajichiqui Diaz | C5: Lesly Nohemí | D5: 39141 | E5: 50 | F5: Dominga Díaz | G5: 4746 7512 | H5: 50 | I5: 50 | J5: 50 | K5: 50 | L5: 50 | M5: 50 | T5: =SUM(H5:S5) -> 300 | W5: 100 | AA5: 100
A6: 1 | B6: Castillo Alay | C6: Reina Marisol | D6: 39506 | E6: 25 | F6: Veralicia Alay Samayoa | G6: 4264 5532 | H6: 50 | I6: 50 | J6: 50 | K6: 50 | L6: 50 | M6: 50 | N6: 50 | T6: =SUM(H6:S6) -> 350 | Z6: 100
A7: 1 | B7: González Yoc | C7: Dulce María José | D7: 38678 | F7: Elsa Eugenia Yoc Xiquin | G7: 5596 0893 | I7: 50 | J7: 50 | K7: 50 | L7: 50 | M7: 50 | N7: 50 | O7: 50 | T7: =SUM(I7:S7) -> 350 | U7: 50 | W7: 100 | X7: 50 | Z7: 100 | AA7: 50
A8: 1 | B8: Higueros Burrión | C8: Emerson Aimar | D8: 38353 | E8: 50 | F8: Celia Yaneth Burrión León | G8: 59915415 | H8: 50 | I8: 50 | J8: 50 | K8: 50 | L8: 50 | T8: =SUM(H8:S8) -> 250 | X8: 200
A9: 1 | B9: Ique González | C9: Daniela Abigail | D9: 40302 | E9: 50 | F9: Daniela Percel Ique | G9: 5013 9540 (Papá) /5976 1478 (Mamá) | H9: 50 | I9: 50 | J9: 50 | K9: 50 | L9: 50 | M9: 50 | N9: 50 | O9: 50 | T9: =SUM(H9:S9) -> 400 | Y9: 200 | AA9: 100
A10: 1 | B10: López Flores | C10: Yamíli Jimena | D10: 39345 | F10: Claudia Elizabet Flores Hernández | G10: 56975230 | H10: 50 | I10: 50 | J10: 50 | K10: 50 | L10: 50 | M10: 50 | N10: 50 | O10: 50 | P10: 50 | Q10: 50 | T10: =SUM(H10:S10) -> 500
A11: 1 | B11: López Ventura | C11: Cristofer Misael | D11: 39846 | F11: Ofelia López Ventura | G11: 4292 3734 | H11: 50 | I11: 50 | J11: 50 | K11: 50 | L11: 50 | M11: 50 | N11: 50 | O11: 50 | P11: 50 | Q11: 50 | T11: =SUM(H11:S11) -> 500 | V11: 200 | Y11: 200
A12: 1 | B12: Mansia Pérez | C12: Edward Steven | D12: 39872 | F12: María del Rosartio Ortiz Rosales | G12: 4811 7364 | H12: 50 | I12: 50 | J12: 50 | K12: 50 | L12: 50 | M12: 50 | N12: 50 | O12: 50 | T12: =SUM(H12:S12) -> 400 | V12: 50 | X12: 100 | Y12: 50 | AA12: 100
A13: 1 | B13: Natareno Toc | C13: Daphne Ahtziri Desiré | D13: 39733 | F13: Dominga Elizabeth Natareno | G13: 35891672 | H13: 50 | I13: 50 | J13: 50 | K13: 50 | L13: 50 | M13: 50 | N13: 50 | O13: 50 | T13: =SUM(H13:S13) -> 400 | V13: 50 | X13: 50 | AA13: 200
A14: 1 | B14: Ponce Suchite | C14: Carmen Sarahi | D14: 39328 | F14: Carmen María Suchite | G14: 5118 3066 | I14: 50 | J14: 50 | K14: 50 | L14: 50 | M14: 50 | N14: 50 | O14: 50 | T14: =SUM(I14:S14) -> 350 | U14: 50 | V14: 50 | W14: 50 | X14: 50 | Y14: 50 | Z14: 50 | AA14: 50
A15: 1 | B15: Sánchez Pérez | C15: Cristian Manuel | D15: 33923 | F15: Cristian Manuel Sánchez | G15: 4178 0069 | I15: 50 | J15: 50 | K15: 50 | T15: =SUM(I15:S15) -> 150 | U15: 50 | V15: 50 | W15: 50
A16: 1 | B16: Velasquez Raxón | C16: Franklin Ricardo | D16: 39648 | F16: Sabrina Siomara Raxón González | G16: 3427 6693 | H16: 50 | I16: 50 | J16: 50 | K16: 50 | L16: 50 | M16: 50 | N16: 50 | O16: 50 | T16: =SUM(H16:S16) -> 400 | V16: 100 | W16: 50 | Y16: 100 | AA16: 100
A17: =SUM(A5:A16) -> 12 | H17: =SUM(H5:H16) -> 450 | I17: =SUM(I5:I16) -> 600 | J17: =SUM(J5:J16) -> 600 | K17: =SUM(K5:K16) -> 600 | L17: =SUM(L5:L16) -> 550 | M17: =SUM(M5:M16) -> 500 | N17: =SUM(N5:N16) -> 450 | O17: =SUM(O5:O16) -> 400 | ... AA17: =SUM(AA5:AA16) -> 700
A27: 21
A28: 22
A29: 23
A30: 24
A31: 25

Sheet 5TO. BACHILLERATO
A2: REGISTRO DE ESTUDIANTES INSCRITOS AL CENTRO DE FORMACIÓN K'ARMEL JUYUP'
A3: AÑO ESCOLAR 2025 | G3: PAGO MENSUALIDAD - 2025
A4: N° | B4: Nombre | C4: Apellidos | D4: Fecha de nacimiento | E4: Encargado/a | F4: Tel. Encargado | G4: ENERO | H4: FEBRERO | I4: MARZO | J4: ABRIL | K4: MAYO | L4: JUNIO | M4: JULIO | N4: AGOSTO | O4: SEPTIEMBRE | P4: OCTUBRE | Q4: NOVIEMBRE | R4: DICIEMBRE | S4: TOTAL | T4: Entregado | U4: Entrega 21 de abril | W4: 45839 | Y4: 1 de septiembre
A5: 1 | B5: Barrios Cuyun | C5: Jaqueline Pamela | D5: 36641 | E5: Jaqueline Pamela | F5: 5785 5344 | S5: =SUM(G5:R5) -> 0
A6: 1 | B6: Gutiérrez Gálvez | C6: Francisco Jesús | D6: 38728 | E6: Dora Luz Gálvez | F6: 5480 3230 | S6: =SUM(H6:R6) -> 0 | T6: 50
A7: 1 | B7: Patzan Díaz | C7: Cristofer Emilio Alejandro | D7: 39439 | E7: Nancy Maribel Díaz Rueda / Ana María Barrientos | F7: 50817240/ 33355710 | S7: =SUM(Q7:R7) -> 0 | T7: 500
A8: 1 | B8: Rodas Villeda | C8: Rodrigo Alexander | D8: 38998 | E8: Ingrid Dinora Cifuentes Cruz | F8: 3575 9655 | G8: 50 | H8: 50 | I8: 50 | J8: 50 | K8: 50 | L8: 50 | M8: 50 | N8: 50 | S8: =SUM(G8:R8) -> 400 | W8: 200
A9: 1 | B9: Velásquez Cano | C9: Sharon Dayan | D9: 39413 | E9: Lesly Saydett Cano | F9: 44589744 | G9: 50 | H9: 50 | I9: 50 | J9: 50 | K9: 50 | S9: =SUM(G9:R9) -> 250 | U9: 150 | X9: 100
A10: =SUM(A5:A9) -> 5 | G10: =SUM(G5:G9) -> 100 | H10: =SUM(H5:H9) -> 100 | I10: =SUM(I5:I9) -> 100 | J10: =SUM(J5:J9) -> 100 | K10: =SUM(K5:K9) -> 100 | L10: =SUM(L5:L9) -> 50 | M10: =SUM(M5:M9) -> 50 | N10: =SUM(N5:N9) -> 50 | ... X10: =SUM(X5:X9) -> 100
A25: 21
A26: 22
A27: 23
A28: 24
A29: 25

Sheet RESUMEN
A1: RESUMEN GENERAL DE DONACIONES MENSUALES
A3: GRADO | B3: TOTAL | C3: ENTREGADO EN DIFERENTES FECHAS | D3: GENERAL DE DONACIONES | E3: Entrega del 01 de abril de 2025 | F3: Entrega del 21 de abril de 2025 | G3: Entrega 30 de mayo de 2025 | H3: Entrega 1 de julio de 2025 | I3: Entrega 4 de agosto | J3: Entrega 1 de septiembre
A4: PRIMERO BÁSICO | B4: ='1ERO. BÁSICO'!T33 -> 9350 | C4: ='1ERO. BÁSICO'!U33 -> 950 | D4: =SUM(B4:C4) -> 10300 | E4: ='1ERO. BÁSICO'!V33 -> 1750 | F4: ='1ERO. BÁSICO'!W33 -> 1450 | G4: ='1ERO. BÁSICO'!X33 -> 900 | H4: ='1ERO. BÁSICO'!Y33 -> 1200 | I4: ='1ERO. BÁSICO'!Z33 -> 1500 | J4: ='1ERO. BÁSICO'!AA33 -> 1100
A5: SEGUNDO BÁSICO | B5: ='2DO. BÁSICO'!T33 -> 7550 | C5: ='2DO. BÁSICO'!U33 -> 1100 | D5: =SUM(B5:C5) -> 8650 | E5: ='2DO. BÁSICO'!V33 -> 1200 | F5: ='2DO. BÁSICO'!W33 -> 900 | G5: ='2DO. BÁSICO'!X33 -> 900 | H5: ='2DO. BÁSICO'!Y33 -> 1200 | I5: ='2DO. BÁSICO'!Z33 -> 1050 | J5: ='2DO. BÁSICO'!AA33 -> 700
A6: TERCERO BÁSICO | B6: ='3ERO. BÁSICO'!T23 -> 4250 | C6: ='3ERO. BÁSICO'!U23 -> 1000 | D6: =SUM(B6:C6) -> 5250 | E6: ='3ERO. BÁSICO'!V23 -> 600 | F6: ='3ERO. BÁSICO'!W23 -> 700 | G6: ='3ERO. BÁSICO'!X23 -> 400 | H6: ='3ERO. BÁSICO'!Y23 -> 1050 | I6: ='3ERO. BÁSICO'!Z23 -> 600 | J6: ='3ERO. BÁSICO'!AA23 -> 500
A7: CUARTO BACHILLERATO | B7: ='4TO. BACHILLERATO'!T17 -> 4350 | C7: ='4TO. BACHILLERATO'!U17 -> 150 | D7: =SUM(B7:C7) -> 4500 | E7: ='4TO. BACHILLERATO'!V17 -> 500 | F7: ='4TO. BACHILLERATO'!W17 -> 350 | G7: ='4TO. BACHILLERATO'!X17 -> 450 | H7: ='4TO. BACHILLERATO'!Y17 -> 600 | I7: ='4TO. BACHILLERATO'!Z17 -> 250 | J7: ='4TO. BACHILLERATO'!AA17 -> 700
A8: QUINTO BACHILLERATO | B8: ='5TO. BACHILLERATO'!S10 -> 650 | C8: ='5TO. BACHILLERATO'!T10 -> 550 | D8: =SUM(B8:C8) -> 1200 | F8: ='5TO. BACHILLERATO'!U10 -> 150 | G8: ='5TO. BACHILLERATO'!V10 -> 0 | H8: ='5TO. BACHILLERATO'!W10 -> 200 | I8: ='5TO. BACHILLERATO'!X10 -> 100 | J8: ='5TO. BACHILLERATO'!Y10 -> 0
B9: =SUM(B4:B8) -> 26150 | C9: =SUM(C4:C8) -> 3750 | D9: =SUM(B9:C9) -> 29900 | E9: =SUM(E4:E8) -> 4050 | F9: =SUM(F4:F8) -> 3550 | G9: =SUM(G4:G8) -> 2650 | H9: =SUM(H4:H8) -> 4250 | I9: =SUM(I4:I8) -> 3500 | J9: =SUM(J4:J8) -> 3000
A12: DESCRIPCIÓN POR MESES
A14: ENERO | B14: ='1ERO. BÁSICO'!H33+'2DO. BÁSICO'!H33+'3ERO. BÁSICO'!H23+'4TO. BACHILLERATO'!H17+'5TO. BACHILLERATO'!G10 -> 2950
A15: FEBRERO | B15: ='1ERO. BÁSICO'!I33+'2DO. BÁSICO'!I33+'3ERO. BÁSICO'!I23+'4TO. BACHILLERATO'!I17+'5TO. BACHILLERATO'!H10 -> 3350
A16: MARZO | B16: ='1ERO. BÁSICO'!J33+'2DO. BÁSICO'!J33+'3ERO. BÁSICO'!J23+'4TO. BACHILLERATO'!J17+'5TO. BACHILLERATO'!I10 -> 3500
A17: ABRIL | B17: ='1ERO. BÁSICO'!K33+'2DO. BÁSICO'!K33+'3ERO. BÁSICO'!K23+'4TO. BACHILLERATO'!K17+'5TO. BACHILLERATO'!J10 -> 3350
A18: MAYO | B18: ='1ERO. BÁSICO'!L33+'2DO. BÁSICO'!L33+'3ERO. BÁSICO'!L23+'4TO. BACHILLERATO'!L17+'5TO. BACHILLERATO'!K10 -> 3450
A19: JUNIO | B19: 50
A20: JULIO | B20: 50
A21: AGOSTO | B21: 50
A22: SEPTIEMBRE | B22: 50
A23: OCTUBRE | B23: 50
B24: =SUM(B14:B23) -> 16850
A27: Pago de Inscripción
A28: Valdez Urbina Jennifer Ximena | J28: 300
A29: Valdez Urbina Jefferson Steven | J29: 300
J30: =SUM(J28:J29) -> 600

Sheet INSCRIPCIÓN 2DO
A1: INSCRIPCIONES 2DO SEMESTRE
A2: Cuarto Bachillerato
A3: N° | B3: Nombre | C3: Apellidos | D3: Pago de Inscripción 2do semestre | E3: Pago impresión de Fotografía | G3: TOTAL A ENTREGAR
A4: 1 | B4: Ajiquichi Diaz | C4: Lesly Nohemí | D4: 600
A5: 2 | B5: Castillo Alay | C5: Reina Marisol | D5: 600
A6: 3 | B6: González Yoc | C6: Dulce María José | D6: 600
A7: 4 | B7: Higueros Burrión | C7: Emerson Aimar
A8: 5 | B8: Ique González | C8: Daniela Abigail | D8: Exonerada
A9: 6 | B9: López Flores | C9: Yamíli Jimena
A10: 7 | B10: López Ventura | C10: Cristofer Misael | D10: 600
A11: 8 | B11: Mansia Pérez | C11: Edward Steven | D11: 600
A12: 9 | B12: Natareno Toc | C12: Daphne Ahtziri Desiré | D12: Exonerada 50%
A13: 10 | B13: Ponce Suchite | C13: Carmen Sarahi | D13: 600
A14: 11 | B14: Velasquez Raxón | C14: Franklin Ricardo | D14: 600
A16: Quinto Bachillerato
A17: 1 | B17: Barrios Cuyun | C17: Jaqueline Pamela | D17: Exonerada | E17: Exonerada
A18: 2 | B18: Gutiérrez Gálvez | C18: Francisco Jesús
A19: 3 | B19: Patzan Díaz | C19: Cristofer Emilio Alejandro | E19: 65
A20: 4 | B20: Rodas Villeda | C20: Rodrigo Alexander | D20: 600 | E20: 65
A21: 5 | B21: Velásquez Cano | C21: Sharon Dayan | D21: 600
E22: =SUM(E17:E21) -> 130
A23: 1 | B23: Cristina Ozuna | C23: Segundo Básico | D23: 200
A24: Entregado el día miércoles 18 de junio: Q. 2100 | D24: =SUM(D4:D23)+E22 -> 5730
A26: Entregado el día lunes 4 de agosto: Q. | C26: =D24-2100 -> 3630

Sheet MULTAS
B1: MULTAS TRABAJO COMUNITARIO
B2: Apellidos | C2: Nombre | D2: Nombre de la Madre | E2: JUNIO | F2: JULIO | G2: AGOSTO | H2: SEPTIEMBRE | I2: OCTUBRE
A3: 1 | B3: Alvarez de la C. | C3: Astrid Dayana | D3: Yesenia de la Cruz García
A4: 2 | B4: Amaya Pérez | C4: Ana Camila Suceth | D4: Diana Sucely Pérez Zelada | E4: 40
A5: 3 | B5: Benito Pérez | C5: Kiara Julissa leilany | D5: María Cristina Pérez Castro
A6: 4 | B6: Chaman | C6: Jessica Paola | D6: Celia Chaman
A7: 5 | B7: Fernández R. | C7: Daniela Jimena | D7: Juana Jeaneth Raymundo Pop
A8: 6 | B8: Gómez R | C8: Abi Michelle | D8: Marta Julia Rodríguez de G. | E8: 40 | F8: 40 | G8: 40
A9: 7 | B9: Gonzáles Yoc | C9: Dulce María | D9: Elsa Eugenia Yoc Xiquin | G9: Lo hizo
A10: 8 | B10: González O | C10: Prisly Adairiz | D10: Amalia Muñoz | E10: 40
A11: 9 | B11: González Sí | C11: Hamilthon Esaú | D11: María Elvira Sí Tot | E11: 40 | F11: 40 | G11: 40
A12: 10 | B12: Gutierrez G. | C12: Francisco Jesús | D12: Dora Luz Gálvez Pú
A13: 11 | B13: Hernández M. | C13: Adam Carlos Enrique | D13: Linda Mendoza Medrano | E13: 40 | F13: 40 | G13: 40 | H13: 40
A14: 12 | B14: Hernández V. | C14: Karely Nicole | D14: Nolvia Lizeth Vargas Orellana
A15: 13 | B15: Ique González | C15: Daniela Abigail | D15: Ruth Abigail González Paredes
A16: 14 | B16: Ismalé Pérez | C16: Antoni Vinicio | D16: Sandra Pérez del Cid
A17: 15 | B17: Jocón Barillas | C17: Emely Julissa | D17: Andrea Betzabé Barrillas V. | E17: 40
A18: 16 | B18: López Flores | C18: Yamíli Jimena | D18: Claudia Elizabeth Flores H.
A19: 17 | B19: López Ventura | C19: Cristofer Misael | D19: Ofelia López Ventura
A20: 18 | B20: Macario Vicente | C20: Rosa Maria | D20: Ana Macario Vicente
A21: 19 | B21: Marroquín O. | C21: Scarlett Dejane D | D21: Scarlett Dejane Marroquín O.
A22: 20 | B22: Martin Ajiatáz | C22: Melany Anahi | D22: Dámaris Ajitáz /Debora
A23: 21 | B23: Mateo Sapón | C23: Tomás Santiago | D23: María Marisela Sapón Sulugüí | G23: 40
A24: 22 | B24: Mauricio López | C24: Wendy Johana | D24: Eva López Mendoza
A25: 23 | B25: Meletz Carrera | C25: Kristen Nicol | D25: Evelin Marleni Carrera Cruz
A26: 24 | B26: Méndez C. | C26: Ángel Ricardo | D26: Gladys Marleni Chávez A.
A27: 25 | B27: Méndez J. | C27: Caterin Helizabeth | D27: Amparo Elizabeth Jacobo Yool
A28: 26 | B28: Molina Case | C28: Jhoshua Gamaliel | D28: Johny Gamaliel Molina C.
A29: 27 | B29: Ochoa Q. | C29: Angelín Daniela | D29: Antonieta Quisquinai Locon
A30: 28 | B30: Ordoñez Zurdo | C30: Pedro Josué | D30: Wendy Marizol Zurdo Batz
A31: 29 | B31: Ozuna Barillas | C31: Ghylaine Cristina | D31: Jesica Mariela Ozuna
A32: 30 | B32: Patzán M. | C32: Cristian Rodolfo | D32: Rudy Rodolfo Patzán Gómez | E32: 40
A33: 31 | B33: Ponce Suchite | C33: Carmen Sarahi | D33: Carmen Maria Suchite M. | E33: 40 | F33: 40 | G33: 40
A34: 32 | B34: Rangel Foronda | C34: Jeferson Omar Israel | D34: Glenda Patricia Foronda H.
A35: 33 | B35: Rivas V. | C35: Martina Fatima Sarai | D35: Reyna Velásquez Ríos
A36: 34 | B36: Rodas Villeda | C36: Rodrigo Alexander | D36: Mario Alfredo Rodas de Leon
A37: 35 | B37: Romero Mendez | C37: Katherine Mariana | D37: María Felisa Mendez Armira
A38: 36 | B38: Roquel Caniche | C38: Edwin David | D38: Reina Aracely Caniche Nicolas | F38: 40
A39: 37 | B39: Saban | C39: María Elizabeth | D39: Victoria Saban | E39: 40 | F39: 40 | G39: 40
A40: 38 | B40: Sánchez Pérez | C40: Cristian Manuel | D40: María Isabel Pérez López
...
