Workbook

Sheet 1ERO. BÁSICO
A1: REGISTRO DE ESTUDIANTES INSCRITOS AL CENTRO DE FORMACIÓN K'ARMEL JUYUP'
A2: AÑO ESCOLAR 2025- 1° Básico
N3: PAGO MENSUALIDAD - 2025
A4: N° | B4: Nombre | C4: Apellidos | D4: Edad | E4: Fecha de nacimiento | F4: Papelería | G4: % Beca | H4: Aporte | I4: Aporte pendiente | J4: Fecha / pago | K4: Recibo N° | L4: Encargado/a | M4: Tel. Encargado | N4: ENERO | O4: FEBRERO | P4: MARZO | Q4: ABRIL | R4: MAYO | S4: JUNIO | T4: JULIO | U4: AGOSTO | V4: SEPTIEMBRE | W4: OCTUBRE | X4: NOVIEMBRE | Y4: DICIEMBRE | Z4: TOTAL
A5: 1 | B5: Álvarez de la Cruz | C5: Astrid Dayana | D5: =TRUNC((TODAY()-E5)/365) -> 13 | E5: 40909 | H5: 600 | L5: Yesenia de la Cruz García | M5: 3909 2709 | Z5: =SUM(N5:Y5) -> 0
A6: 1 | B6: Amaya Pérez | C6: Ana Camila Suceth | D6: =TRUNC((TODAY()-E6)/365) -> 14 | E6: 40777 | F6: Exp. Escolar | G6: 0.25 | H6: 600 | L6: Ingrid Aracely Zelada Chinchilla | M6: 5961 2899 | Z6: =SUM(N6:Y6) -> 0
A7: 1 | B7: Armis | C7: Ángel Manuel | D7: =TRUNC((TODAY()-E7)/365) -> 14 | E7: 40591 | F7: Exp. Escolar | H7: 800 | K7: 37 | L7: María Boch/ Claudia Armis Boch (mamá) | M7: 3990 5979 (Abuela) 45381094 (Mamá) | N7: 50 | O7: 50 | P7: 50 | Q7: 50 | Z7: =SUM(N7:Y7) -> 200
A8: 1 | B8: Batres Echeverria | C8: Marco Antonio | D8: =TRUNC((TODAY()-E8)/365) -> 14 | E8: 40766 | F8: Exp. Escolar | H8: 600 | K8: 13 | L8: Jubitza Echeverría Contreras | M8: 5045 7969 | Z8: =SUM(N8:Y8) -> 0
A9: 1 | B9: Bonilla | C9: Jhorgeysil Ayleen | D9: =TRUNC((TODAY()-E9)/365) -> 13 | E9: 41068 | F9: Exp. Escolar | G9: 0.5 | H9: 300 | I9: 300 | K9: 15 y 55 | L9: Silvia Azucena Bonilla Vanegas | M9: 3913 4349 | Z9: =SUM(N9:Y9) -> 0
A10: 1 | B10: Flores Soyoy | C10: Angie Delyanne | D10: =TRUNC((TODAY()-E10)/365) -> 13 | E10: 41048 | F10: Exp. Escolar | H10: 600 | J10: Diciembre | K10: 14 | L10: Julissa Xiomara Soyoy Tuquer | M10: 3709 6020 | Z10: =SUM(N10:Y10) -> 0
A11: 1 | B11: Gómez Rodríguez | C11: Abi Michelle | D11: =TRUNC((TODAY()-E11)/365) -> 13 | E11: 41145 | F11: Exp. Escolar | H11: 700 | I11: 0 | J11: 29 de noviembre | K11: 1 | L11: Marta Julia Rodríguez | M11: 5615 4185 | N11: 50 | O11: 50 | Z11: =SUM(N11:Y11) -> 100
A12: 1 | B12: González Ordoñez | C12: Prisly Adairiz | D12: =TRUNC((TODAY()-E12)/365) -> 14 | E12: 40624 | F12: Exp. Escolar | H12: 600 | L12: Amalia Muñoz | M12: 5124 2275 | Z12: =SUM(N12:Y12) -> 0
A13: 1 | B13: González Sí | C13: Hamilthon Esaú | D13: =TRUNC((TODAY()-E13)/365) -> 13 | E13: 40845 | F13: Exp. Escolar | H13: 600 | J13: Final de noviembre | K13: 18 y 49 | L13: María Elvira Sí Tot | M13: 4358 6033 | Z13: =SUM(N13:Y13) -> 0
A14: 1 | B14: Jiménez Soyoy | C14: Sharon Alejandra | D14: =TRUNC((TODAY()-E14)/365) -> 14 | E14: 40451 | F14: Exp. Escolar | G14: 50 | H14: 600 | L14: María Fernanda Miranda Paredes | M14: 4144 6981 | Z14: =SUM(N14:Y14) -> 0
A15: 1 | B15: Juárez Escalante | C15: Lisandro Saúl | D15: =TRUNC((TODAY()-E15)/365) -> 13 | E15: 41011 | F15: Exp. Escolar | H15: 650 | J15: 17 de diciembre | K15: 57 | L15: Gumercinda Concepción Escalante Hernández | M15: 5699 3330 | N15: 50 | Z15: =SUM(N15:Y15) -> 50
A16: 1 | B16: Macario Vicente | C16: Rosa María | D16: =TRUNC((TODAY()-E16)/365) -> 14 | E16: 40763 | F16: Exp. Escolar | G16: 50 | H16: 600 | I16: 0 | J16: Diciembre | L16: Ana Macario Vicente | M16: 5868 2459 | Z16: =SUM(N16:Y16) -> 0
A17: 1 | B17: Mateo Sapón | C17: Tomás Santiago | D17: =TRUNC((TODAY()-E17)/365) -> 11 | E17: 41591 | H17: 600 | L17: María Maricela Sapón Sulugüi | M17: 3296 5044 | Z17: =SUM(N17:Y17) -> 0
A18: 1 | B18: Montes Arreola | C18: Austin Daniel | D18: =TRUNC((TODAY()-E18)/365) -> 13 | E18: 41018 | F18: Exp. Escolar | H18: 600 | K18: 7 | L18: Paula Melissa Estrada Arreola | M18: 5932 1086 | N18: 50 | O18: 50 | P18: 50 | Z18: =SUM(N18:Y18) -> 150
A19: 1 | B19: Natareno Toc | C19: Jeffrey Mateo | D19: =TRUNC((TODAY()-E19)/365) -> 14 | E19: 40784 | F19: Exp. Escolar | H19: 600 | K19: 54 | L19: Domingo Elizabeth Natareno | M19: 3589 1672 | N19: 50 | Z19: =SUM(N19:Y19) -> 50
A20: 1 | B20: Patzán Hernández | C20: Mario Martin | D20: =TRUNC((TODAY()-E20)/365) -> 14 | E20: 40595 | F20: Exp. Escolar | G20: 0.5 | H20: 300 | I20: 300 | J20: enero, febrero, marzo | K20: 5 | L20: Mario Martín Patzán Ortiz | M20: 36921603 | Z20: =SUM(N20:Y20) -> 0
A21: 1 | B21: Rodas Zurdo | C21: Diego Andreé | D21: =TRUNC((TODAY()-E21)/365) -> 13 | E21: 40992 | F21: Exp. Escolar | H21: 600 | J21: 29 de noviembre | K21: 02 y 041 | L21: Andrea Paola Zurdo Batz | M21: 3304 9629 | Z21: =SUM(N21:Y21) -> 0
A22: 1 | B22: Romero Méndez | C22: Katherine Mariana | D22: =TRUNC((TODAY()-E22)/365) -> 14 | E22: 40645 | F22: Exp. Escolar | H22: 600 | K22: 9 y 25 | Z22: =SUM(N22:Y22) -> 0
A23: 1 | B23: Roquel Caniche | C23: Edwin David | D23: =TRUNC((TODAY()-E23)/365) -> 13 | E23: 40934 | F23: Exp. Escolar | H23: 650 | J23: Enero y Febrero | K23: 8 | L23: Reina Araceli Caniche Nicolás | M23: 5113 9210 | N23: 50 | Z23: =SUM(N23:Y23) -> 50
A24: 1 | B24: Soc Grande | C24: Norman Isaac | D24: =TRUNC((TODAY()-E24)/365) -> 13 | E24: 40888 | H24: 1100 | L24: Beatriz Soc | M24: 4844 2237 | N24: 50 | O24: 50 | P24: 50 | Q24: 50 | R24: 50 | S24: 50 | T24: 50 | U24: 50 | V24: 50 | W24: 50 | Z24: =SUM(N24:Y24) -> 500
A25: 1 | B25: Váldez Urbina | C25: Jennyfer Ximena | D25: =TRUNC((TODAY()-E25)/365) -> 14 | E25: 40665 | F25: Exp. Escolar | G25: 0.5 | H25: 300 | I25: 300 | J25: Enero | K25: 11 | L25: Julia Virginia Urbina Váldez | M25: 36921477 | Z25: =SUM(N25:Y25) -> 0
A26: 1 | B26: Rivas Velásquez | C26: Martina Fátima Saraí | D26: =TRUNC((TODAY()-E26)/365) -> 14 | E26: 40661 | F26: Exp. Escolar | H26: 600 | J26: Primera semana diciembre | K26: 19 | L26: Reyna Josefina Velásquez Ríos | M26: 58335953 | Z26: =SUM(N26:Y26) -> 0
A27: 1 | B27: Contreras Corea | C27: Alberth de Jesús | D27: =TRUNC((TODAY()-E27)/365) -> 14 | E27: 40791 | F27: Exp. Escolar | H27: 600 | J27: Enero | L27: Karla Corea | M27: 4742 4386 | Z27: =SUM(N27:Y27) -> 0
A28: 1 | B28: Ismalé Pérez | C28: Antoni Vinicio | D28: =TRUNC((TODAY()-E28)/365) -> 16 | E28: 39800 | F28: Exp. Escolar | H28: 600 | K28: 3 y 28 | L28: Sandra Pérez | M28: 5693 4232 | Z28: =SUM(N28:Y28) -> 0
A29: 1 | B29: Simón Peren | C29: Candy Fabiola Odeth | D29: =TRUNC((TODAY()-E29)/365) -> 12 | E29: 41491 | H29: 650 | L29: Elvira Peren Otzoy | M29: 3622 3361 | N29: 50
A30: 1 | B30: Molina Case | C30: Jhoshua Gamaliel | D30: =TRUNC((TODAY()-E30)/365) -> 13 | E30: 40881 | H30: 600 | L30: Jonny Gamaliel Molina Contreras | M30: 3591 1949
A31: 1 | B31: Benito Pérez | C31: Kiara Julissa Leilany | D31: =TRUNC((TODAY()-E31)/365) -> 14 | E31: 40528 | H31: 300 | I31: 300 | J31: Diciembre | L31: Jezly Robersy Mirella Benito López | M31: 4006 3989
A32: =SUM(A5:A31) -> 27 | H32: =SUM(H5:H31) -> 15950 | I32: =SUM(I5:I28) -> 900 | Z32: =SUM(Z5:Z28) -> 1100

Sheet 2DO. BÁSICO
A2: REGISTRO DE ESTUDIANTES INSCRITOS AL CENTRO DE FORMACIÓN K'ARMEL JUYUP'
A3: AÑO ESCOLAR 2025- 2° Básico | N3: PAGO MENSUALIDAD - 2025
A4: N° | B4: Nombre | C4: Apellidos | D4: Edad | E4: Fecha de nacimiento | F4: Papelería | G4: % Beca | H4: Aporte | I4: Aporte pendiente | J4: Fecha de pago | K4: Recibo N° | L4: Encargado/a | M4: Tel. Encargado | N4: ENERO | O4: FEBRERO | P4: MARZO | Q4: ABRIL | R4: MAYO | S4: JUNIO | T4: JULIO | U4: AGOSTO | V4: SEPTIEMBRE | W4: OCTUBRE | X4: NOVIEMBRE | Y4: DICIEMBRE | Z4: TOTAL
A5: 1 | B5: Carrera Lobos | C5: Mia Scarlet Susana | D5: =TRUNC((TODAY()-E5)/365) -> 14 | E5: 40583 | G5: 25 | H5: 600 | J5: Diciembre | L5: Verónica Patricia Lobos | M5: 4221 5210 | Z5: =SUM(N5:Y5) -> 0
A6: 1 | B6: Chocoj Rodríguez | C6: Candy Mishelle | D6: =TRUNC((TODAY()-E6)/365) -> 14 | E6: 40738 | F6: Exp. Escolar | H6: 600 | J6: Enero | K6: 16 | L6: Enma Edelmira Rodríguez Estrada | M6: 5693 9034 | Z6: =SUM(N6:Y6) -> 0
A7: 1 | B7: Fernández Raymundo | C7: Daniela Jimena | D7: =TRUNC((TODAY()-E7)/365) -> 17 | E7: 39569 | G7: 50 | H7: 500 | I7: 100 | J7: Enero | K7: 42 | L7: Juana Janeth Raymundo Pop | M7: 3010 0349 | Z7: =SUM(N7:Y7) -> 0
A8: 1 | B8: Hernández Mendoza | C8: Adam Carlos Enrique | D8: =TRUNC((TODAY()-E8)/365) -> 16 | E8: 39995 | F8: Papelería entregada | G8: 0.25 | H8: 700 | L8: Linda Ssusset Mendoza Medrano | M8: 3813 3938 | N8: 50 | O8: 50 | Z8: =SUM(N8:Y8) -> 100
A9: 1 | B9: Hernández Vargas | C9: Karely Nicole | D9: =TRUNC((TODAY()-E9)/365) -> 14 | E9: 40604 | H9: 600 | K9: 38 | L9: Nolvia Liseth Vargas Orellana | M9: 36127776 | Z9: =SUM(N9:Y9) -> 0
A10: 1 | B10: Higueros Burrión | C10: Alexandra Anahí Yanet | D10: =TRUNC((TODAY()-E10)/365) -> 18 | E10: 39256 | G10: 50 | H10: 600 | J10: Diciembre | L10: Celia Yaneth Burrión León | M10: 59915415 | Z10: =SUM(N10:Y10) -> 0
A11: 1 | B11: Marroquín Orantes | C11: Scarlett Dajane | D11: =TRUNC((TODAY()-E11)/365) -> 14 | E11: 40711 | H11: 800 | J11: Primer semana de dicembre | L11: Gloria Mirna Orantes | M11: 50636279 | N11: 50 | O11: 50 | P11: 50 | Q11: 50 | Z11: =SUM(N11:Y11) -> 200
A12: 1 | B12: Martin Ajiatáz | C12: Melany Anahí | D12: =TRUNC((TODAY()-E12)/365) -> 17 | E12: 39345 | F12: Exp. Escolar | G12: 25 | H12: 600 | J12: Diciembre y enero | K12: 44 | L12: Debora Raquel Ajiatás Hernández | M12: 5855 9961 | Z12: =SUM(N12:Y12) -> 0
A13: 1 | B13: Meletz Carrera | C13: Kristen Nicol | D13: =TRUNC((TODAY()-E13)/365) -> 15 | E13: 40406 | F13: Exp. Escolar | H13: 600 | K13: 4 | L13: Evelin Marleni Carrera Cruz | M13: 4443 1110 | Z13: =SUM(N13:Y13) -> 0
A14: 1 | B14: Méndez Ijchajchal | C14: Jeremy Alexis | D14: =TRUNC((TODAY()-E14)/365) -> 14 | E14: 40693 | H14: 600 | K14: 22 | L14: Dolores Ijchajchal Gónzalez | M14: 45232828 | Z14: =SUM(N14:Y14) -> 0
A15: 1 | B15: Morales Agustín | C15: Ilbia Rosalia | D15: =TRUNC((TODAY()-E15)/365) -> 14 | E15: 40478 | H15: 650 | K15: 43 | L15: Ilbia Rosal+ia Agustín Yol | M15: 3795 0050 | N15: 50 | Z15: =SUM(N15:Y15) -> 50
A16: 1 | B16: Ordoñez Zurdo | C16: Pedro Josué | D16: =TRUNC((TODAY()-E16)/365) -> 16 | E16: 39855 | H16: 600 | K16: 20 | L16: Andrea Paola Zurdo Batz | M16: 3304 9620 (WhatsApp) 4844 0150 ( Llamadas) | Z16: =SUM(N16:Y16) -> 0
A17: 1 | B17: Ordoñez Zurdo | C17: Julio Alejandro Jeremiah | D17: =TRUNC((TODAY()-E17)/365) -> 16 | E17: 40004 | H17: 600 | K17: 21 | L17: Andrea Paola Zurdo Batz | M17: 3304 9620 (WhatsApp) 4844 0150 ( Llamadas) | Z17: =SUM(N17:Y17) -> 0
A18: 1 | B18: Patzan Díaz | C18: Sherlin Esmeralda | D18: =TRUNC((TODAY()-E18)/365) -> 14 | E18: 40615 | H18: 1100 | J18: Última semana de noviembre | K18: 46 | L18: Nancy Maribel Díaz Rueda/Ana María Barrientos | M18: 50817240/ 33355710 | N18: 50 | O18: 50 | P18: 50 | Q18: 50 | R18: 50 | S18: 50 | T18: 50 | U18: 50 | V18: 50 | W18: 50 | Z18: =SUM(N18:Y18) -> 500
A19: 1 | B19: Rafael Baíl | C19: Damaris Anay | D19: =TRUNC((TODAY()-E19)/365) -> 14 | E19: 40753 | H19: 600 | J19: Última semana de noviembre | K19: 35 | L19: Ofelia Baíl Gómez | M19: 4576 9306 | N19: 50 | O19: 50 | Z19: =SUM(N19:Y19) -> 100
A20: 1 | B20: Rangel Foronda | C20: Jeferson Omar Israel | D20: =TRUNC((TODAY()-E20)/365) -> 15 | E20: 40287 | G20: 25 | H20: 600 | J20: Diciembre | K20: 26 | L20: Glenda Patricia Foronda | M20: 5976 1035 | Z20: =SUM(N20:Y20) -> 0
A21: 1 | B21: Salalá Soyos | C21: Mildre Aracely | D21: =TRUNC((TODAY()-E21)/365) -> 17 | E21: 39670 | G21: 25 | H21: 600 | J21: Diciembre | K21: 51 y 59 | L21: María Sandra Soyos Xocoxic | M21: 4574 4662 | Z21: =SUM(N21:Y21) -> 0
A22: 1 | B22: Salala Soyos | C22: Jocelyn Mchelle | D22: =TRUNC((TODAY()-E22)/365) -> 14 | E22: 40479 | G22: 25 | H22: 600 | J22: Diembre | K22: 52 | L22: María Sandra Soyos Xocoxic | M22: 4574 4662 | Z22: =SUM(N22:Y22) -> 0
A23: 1 | B23: Solis Salguero | C23: Iñaki Lorenzo Antonio | D23: =TRUNC((TODAY()-E23)/365) -> 14 | E23: 40528 | G23: 50 | H23: 700 | I23: 0 | J23: Diciembre | K23: 24 | L23: Hilda Salguero | M23: 41859786 | N23: 50 | O23: 50 | Z23: =SUM(N23:Y23) -> 100
A24: 1 | B24: Toledo Chiquitó | C24: Kristofer Augusto | D24: =TRUNC((TODAY()-E24)/365) -> 16 | E24: 39975 | H24: 650 | J24: Primera semana de diciembre | L24: Aura Estela Chiquitó | M24: 3118 0246 | N24: 50 | Z24: =SUM(N24:Y24) -> 50
A25: 1 | B25: Tzul Quiñónez | C25: Londy María | D25: =TRUNC((TODAY()-E25)/365) -> 16 | E25: 39839 | H25: 700 | K25: 23 | L25: María Nieves García | M25: 5182 6697 | N25: 50 | O25: 50 | Z25: =SUM(N25:Y25) -> 100
A26: 1 | B26: Yoque Domingo | C26: Erick Andrés | D26: =TRUNC((TODAY()-E26)/365) -> 15 | E26: 40253 | H26: 300 | I26: 300 | J26: Dos cuotas | L26: Carolina Jasmin Yoque Domingo | M26: 3737 0430 | Z26: =SUM(N26:Y26) -> 0
A27: 1 | B27: Contreras Corea | C27: Sharóm Solansh Gabriela | D27: =TRUNC((TODAY()-E27)/365) -> 15 | E27: 40366 | F27: Exp. Escolar | H27: 600 | J27: Primera semana de diciembre | L27: Karla Corea | M27: 4742 4386 | Z27: =SUM(N27:Y27) -> 0
A28: 1 | B28: Ozuna Barillas | C28: Ghylaine Cristina | D28: =TRUNC((TODAY()-E28)/365) -> 15 | E28: 40269 | H28: 600 | J28: Primera semana de diciembre | L28: Jessica Mariela Ozuna Barillas | M28: 49190774 | Z28: =SUM(N28:Y28) -> 0
A29: 1 | B29: Morataya Patzán | C29: Estefany Paola | D29: =TRUNC((TODAY()-E29)/365) -> 14 | E29: 40718 | H29: 300 | I29: 300 | L29: María de los Ángeles Patzán | M29: 4295 7039
A30: 1 | B30: Fernández Reyes | C30: William Jesús | D30: =TRUNC((TODAY()-E30)/365) -> 14 | E30: 40458 | H30: 600 | J30: Febrero | L30: Mayra Marilú Reyes Chilin | M30: 5965 0988
A31: 1 | B31: Gutiérrez Salazar | C31: Ligia Virginia | D31: =TRUNC((TODAY()-E31)/365) -> 14 | E31: 40509 | H31: 600 | L31: Ana Mabely Salazar Flores | M31: 4939 5804
A32: =SUM(A5:A31) -> 27 | H32: =SUM(H5:H31) -> 16600 | I32: =SUM(I5:I26) -> 400 | Z32: =SUM(Z5:Z28) -> 1200

Sheet 3ERO. BÁSICO
A2: REGISTRO DE ESTUDIANTES INSCRITOS AL CENTRO DE FORMACIÓN K'ARMEL JUYUP'
A3: AÑO ESCOLAR 2025 - 3° Básico | N3: PAGO MENSUALIDAD - 2025
A4: N° | B4: Nombre | C4: Apellidos | D4: Edad | E4: Fecha de nacimiento | F4: Papelería | G4: % Beca | H4: Aporte | I4: Aporte pendiente | J4: Fecha de pago | K4: Recibo N° | L4: Encargado/a | M4: Tel. Encargado | N4: ENERO | O4: FEBRERO | P4: MARZO | Q4: ABRIL | R4: MAYO | S4: JUNIO | T4: JULIO | U4: AGOSTO | V4: SEPTIEMBRE | W4: OCTUBRE | X4: NOVIEMBRE | Y4: DICIEMBRE | Z4: TOTAL
B5: Camey Osorio | C5: Gloria Karina | D5: 14 | Z5: =SUM(N5:Y5) -> 0
A6: 1 | B6: Chaman | C6: Jessica Paola | D6: =TRUNC((TODAY()-E6)/365) -> 16 | E6: 40002 | H6: 1100 | K6: 29 | L6: Celia Chamán | M6: 47616125 | N6: 50 | O6: 50 | P6: 50 | Q6: 50 | R6: 50 | S6: 50 | T6: 50 | U6: 50 | V6: 50 | W6: 50 | X6: 50 | Z6: =SUM(N6:Y6) -> 550
B7: Cuc Gonzáles | C7: Naomi Susana | D7: =TRUNC((TODAY()-E7)/365) -> 15 | E7: 40135 | H7: 300 | I7: 300 | K7: 63 | L7: Marly Susana Cuc González | Z7: =SUM(N7:Y7) -> 0
A8: 1 | B8: Figueroa Martínez | C8: Eddy Randolfo | D8: =TRUNC((TODAY()-E8)/365) -> 16 | E8: 40030 | H8: 800 | J8: Primera semana de diciembre | K8: 39 y 58 | L8: Mayra Ester Aguilar/Huberto Randolfo Figueroa Natareno | M8: 3191 2974 (Abuela)/59003561 (Abuelo) | N8: 50 | O8: 50 | P8: 50 | Q8: 50 | Z8: =SUM(N8:Y8) -> 200
A9: 1 | B9: Jocón Barillas | C9: Emily Julissa | D9: =TRUNC((TODAY()-E9)/365) -> 16 | E9: 40041 | H9: 800 | K9: 34 | L9: Andrea Betzabé Barillas Villanueva | M9: 4964 7451 | N9: 50 | O9: 50 | P9: 50 | Q9: 50 | Z9: =SUM(N9:Y9) -> 200
A10: 1 | B10: Mauricio López | C10: Wendy Johana | D10: =TRUNC((TODAY()-E10)/365) -> 15 | E10: 40329 | H10: 150 | I10: 450 | K10: 50 | L10: Eva López | M10: 46345995 | Z10: =SUM(N10:Y10) -> 0
B11: Méndez Jacobo | C11: Caterine Helizabeth | D11: =TRUNC((TODAY()-E11)/365) -> 15 | E11: 40191 | F11: Exp. Escolar | G11: 0.25 | H11: 600 | I11: 0 | J11: Primera semana de enero | K11: 6 | L11: Amparo Elizabeth Jacobo Yool | M11: 5669 1790/51853591 (Papá Robin Méndez) | Z11: =SUM(N11:Y11) -> 0
A12: 1 | B12: Ochoa Quisquina | C12: Angelin Daniela | D12: =TRUNC((TODAY()-E12)/365) -> 15 | E12: 40191 | G12: 50 | I12: 600 | J12: Fin de noviembre | L12: Antonieta Quisquina Locón | M12: 45913845 | Z12: =SUM(N12:Y12) -> 0
A13: 1 | B13: Ortíz Yax | C13: Axel Emanuel | D13: =TRUNC((TODAY()-E13)/365) -> 15 | E13: 40363 | G13: 50 | H13: 400 | I13: 200 | J13: Diciembre | K13: 32 | L13: Evelyn Marleni Yax | M13: 50121187 | Z13: =SUM(N13:Y13) -> 0
A14: 1 | B14: Patzán Morales | C14: Cristian Rodolfo | D14: =TRUNC((TODAY()-E14)/365) -> 15 | E14: 40373 | H14: 400 | I14: 200 | L14: Rudy Rodolfo Patzán Gómez | Z14: =SUM(N14:Y14) -> 0
A15: 1 | B15: Quisquina Locon | C15: Axel Eduardo | D15: =TRUNC((TODAY()-E15)/365) -> 16 | E15: 39821 | G15: 50 | I15: 600 | J15: Noviembre | L15: Antonieta Quisquina Locón | M15: 45913845 | Z15: =SUM(N15:Y15) -> 0
A16: 1 | B16: Saban | C16: María Elizabeth de la Soledad | D16: =TRUNC((TODAY()-E16)/365) -> 16 | E16: 39754 | G16: 50 | H16: 850 | I16: 0 | J16: Noviembre | K16: 36 | L16: Victoria Sabán | M16: 4502 8704 | N16: 50 | O16: 50 | P16: 50 | Q16: 50 | R16: 50 | Z16: =SUM(N16:Y16) -> 250
A17: 1 | B17: Santizo de León | C17: Wilson Alexander | D17: =TRUNC((TODAY()-E17)/365) -> 17 | E17: 39610 | H17: 600 | K17: 61 | Z17: =SUM(N17:Y17) -> 0
A18: 1 | B18: Sicay Pérez | C18: Mayda Nicol | H18: 600 | I18: 0 | L18: Fermina Pérez Pérez | M18: 3982 1733 | Z18: =SUM(N18:Y18) -> 0
A19: 1 | B19: Subuyuj Morales | C19: Angelly Marleni Noemy | D19: =TRUNC((TODAY()-E19)/365) -> 16 | E19: 39963 | G19: 50 | H19: 600 | J19: Enero | K19: 31 | L19: Ana Marleni Morales Castillo | M19: 43393260 | Z19: =SUM(N19:Y19) -> 0
A20: 1 | B20: Tiul Coc | C20: Jayra Baneza | D20: =TRUNC((TODAY()-E20)/365) -> 16 | E20: 39849 | H20: 650 | K20: 48 | L20: Hermelindo Tiul Coc | M20: 3044 4545 | N20: 50 | Z20: =SUM(N20:Y20) -> 50
A21: 1 | B21: Váldez Urbina | C21: Jefersón Estiven | D21: =TRUNC((TODAY()-E21)/365) -> 16 | E21: 39724 | H21: 600 | I21: 300 | J21: enero | K21: 12 | L21: Julia Urbina | M21: 3692 1477 | Z21: =SUM(N21:Y21) -> 0
A22: 1 | B22: Méndez Chávez | C22: Ángel Ricardo | D22: =TRUNC((TODAY()-E22)/365) -> 17 | E22: 39539 | F22: Exp. Escolar | H22: 600 | J22: Primera semana de diciembre | K22: 17 | L22: Juan Ramón Chavez Alvarado | M22: 4761 9083 | Z22: =SUM(N22:Y22) -> 0
A23: 1 | B23: Villagrán Mijangos | C23: Katheryn Amarylis | D23: =TRUNC((TODAY()-E23)/365) -> 16 | E23: 39826 | H23: 650 | K23: 30 | L23: Juan Carlois Villagrán | M23: 41343873 | N23: 50 | Z23: =SUM(N23:Y23) -> 50
A24: 1 | B24: Peren Otzoy | C24: Randy Alexander | H24: 650 | N24: 50
A25: 1 | B25: Molina Case | C25: Maryury Daniela | D25: =TRUNC((TODAY()-E25)/365) -> 16 | E25: 39997 | F25: Pendiente papelería | H25: 600 | J25: Febrero | L25: Yuvicsa Ninnet Case | M25: 4105 8068/51100327
A26: =SUM(A5:A25) -> 18 | H26: =SUM(H5:H25) -> 10950 | I26: =SUM(I5:I23) -> 2650 | Z26: =SUM(Z5:Z23) -> 1300

Sheet 4TO. BACHILLERATO
A2: REGISTRO DE ESTUDIANTES INSCRITOS AL CENTRO DE FORMACIÓN K'ARMEL JUYUP'
A3: AÑO ESCOLAR 2025. 4° Bachillerato | N3: PAGO MENSUALIDAD - 2025
A4: N° | B4: Nombre | C4: Apellidos | D4: Edad | E4: Fecha de nacimiento | F4: Papelería | G4: % Beca | H4: Aporte | I4: Aporte pendiente | J4: Fecha de pago | K4: Recibo N° | L4: Encargado/a | M4: Tel. Encargado | N4: ENERO | O4: FEBRERO | P4: MARZO | Q4: ABRIL | R4: MAYO | S4: JUNIO | T4: JULIO | U4: AGOSTO | V4: SEPTIEMBRE | W4: OCTUBRE | X4: NOVIEMBRE | Y4: DICIEMBRE | Z4: TOTAL
A5: 1 | B5: Ajichiqui Diaz | C5: Lesly Nohemí | D5: =TRUNC((TODAY()-E5)/365) -> 18 | E5: 39141 | G5: 50 | H5: 600 | K5: 65 | L5: Dominga Díaz | M5: 4746 7512 | Z5: =SUM(N5:Y5) -> 0
A6: 1 | B6: Castillo Alay | C6: Reina Marisol | D6: =TRUNC((TODAY()-E6)/365) -> 17 | E6: 39506 | G6: 25 | H6: 650 | K6: 47 | L6: Veralicia Alay Samayoa | M6: 4264 5532 | N6: 50 | Z6: =SUM(N6:Y6) -> 50
A7: 1 | B7: Higueros Burrión | C7: Emerson Aimar | D7: =TRUNC((TODAY()-E7)/365) -> 20 | E7: 38353 | G7: 50 | H7: 600 | L7: Celia Yaneth Burrión León | M7: 59915415 | Z7: =SUM(N7:Y7) -> 0
A8: 1 | B8: Ique González | C8: Daniela Abigail | D8: =TRUNC((TODAY()-E8)/365) -> 15 | E8: 40302 | G8: 50 | H8: 600 | J8: Diciembre | L8: Daniela Percel Ique | M8: 5013 9540 (Papá) /5976 1478 (Mamá) | Z8: =SUM(N8:Y8) -> 0
A9: 1 | B9: Natareno Toc | C9: Daphne Ahtziri Desiré | D9: =TRUNC((TODAY()-E9)/365) -> 16 | E9: 39733 | F9: Exp. Escolar | G9: 50 | H9: 650 | K9: 53 | L9: Dominga Elizabeth Natareno | M9: 35891672 | N9: 50 | Z9: =SUM(N9:Y9) -> 50
B10: Urizar Poroj | C10: Danna Fernanda | D10: =TRUNC((TODAY()-E10)/365) -> 125 | Z10: =SUM(N10:Y10) -> 0
A11: 1 | B11: Mansia Pérez | C11: Edward Steven | D11: =TRUNC((TODAY()-E11)/365) -> 16 | E11: 39872 | H11: 600 | K11: 10 | L11: María del Rosartio Ortiz Rosales | M11: 4811 7364 | Z11: =SUM(N11:Y11) -> 0
B12: Xiloj Rueda | C12: Michael Alexander | D12: =TRUNC((TODAY()-E12)/365) -> 22 | E12: 37524 | F12: Certificado de 3 básico, Nacimiento, Fotocopia de DPI | I12: 600 | J12: Primera semana de diciembre | L12: Reginalda Rueda Florian | M12: 5524 4412 | Z12: =SUM(N12:Y12) -> 0
A13: 1 | B13: López Flores | C13: Yamíli Jimena | D13: =TRUNC((TODAY()-E13)/365) -> 17 | E13: 39345 | H13: 1700 | K13: 27 | L13: Claudia Elizabet Flores Hernández | M13: 56975230 | N13: 50 | O13: 50 | P13: 50 | Q13: 50 | R13: 50 | S13: 50 | T13: 50 | U13: 50 | V13: 50 | W13: 50 | Z13: =SUM(N13:Y13) -> 500
A14: 1 | B14: López Ventura | C14: Cristofer Misael | D14: =TRUNC((TODAY()-E14)/365) -> 16 | E14: 39846 | G14: 50 | H14: 650 | L14: Ofelia López Ventura | M14: 4292 3734 | N14: 50
A15: 1 | B15: Sánchez Pérez | C15: Cristian Manuel | D15: =TRUNC((TODAY()-E15)/365) -> 32 | E15: 33923 | H15: 650 | L15: Cristian Manuel Sánchez | M15: 4178 0069 | N15: 50
A16: 1 | B16: Ponce Suchite | C16: Carmen Sarahi | D16: =TRUNC((TODAY()-E16)/365) -> 18 | E16: 39328 | H16: 650 | L16: Carmen María Suchite | M16: 5118 3066 | N16: 50
A17: 1 | B17: Velasquez Raxón | C17: Franklin Ricardo | D17: =TRUNC((TODAY()-E17)/365) -> 17 | E17: 39648 | H17: 600 | L17: Sabrina Siomara Raxón González | M17: 3427 6693
A18: 1 | B18: González Yoc | C18: Dulce María José | D18: =TRUNC((TODAY()-E18)/365) -> 19 | E18: 38678 | H18: 650 | L18: Elsa Eugenia Yoc Xiquin | M18: 5596 0893 | N18: 50
A19: =SUM(A5:A18) -> 12 | H19: =SUM(H5:H18) -> 8600 | I19: =SUM(I5:I13) -> 600 | Z19: =SUM(Z5:Z13) -> 600
A29: 21
A30: 22
A31: 23
A32: 24
A33: 25

Sheet 5TO. BACHILLERATO
A2: REGISTRO DE ESTUDIANTES INSCRITOS AL CENTRO DE FORMACIÓN K'ARMEL JUYUP'
A3: AÑO ESCOLAR 2025 | N3: PAGO MENSUALIDAD - 2025
A4: N° | B4: Nombre | C4: Apellidos | D4: Edad | E4: Fecha de nacimiento | F4: Papelería | G4: % Beca | H4: Aporte | I4: Aporte pendiente | J4: Fecha de pago | K4: Recibo N° | L4: Encargado/a | M4: Tel. Encargado | N4: ENERO | O4: FEBRERO | P4: MARZO | Q4: ABRIL | R4: MAYO | S4: JUNIO | T4: JULIO | U4: AGOSTO | V4: SEPTIEMBRE | W4: OCTUBRE | X4: NOVIEMBRE | Y4: DICIEMBRE | Z4: TOTAL
A5: 1 | B5: Barrios Cuyun | C5: Jaqueline Pamela | D5: =TRUNC((TODAY()-E5)/365) -> 25 | E5: 36641 | G5: 1 | H5: 600 | L5: Jaqueline Pamela | M5: 5785 5344 | Z5: =SUM(N5:Y5) -> 0
A6: 1 | B6: Gutiérrez Gálvez | C6: Francisco Jesús | D6: =TRUNC((TODAY()-E6)/365) -> 19 | E6: 38728 | H6: 650 | L6: Dora Luz Gálvez | M6: 5480 3230 | N6: 50 | Z6: =SUM(N6:Y6) -> 50
A7: 1 | B7: Patzan Díaz | C7: Cristofer Emilio Alejandro | D7: =TRUNC((TODAY()-E7)/365) -> 17 | E7: 39439 | H7: 1700 | K7: 45 | L7: Nancy Maribel Díaz Rueda/Ana María Barrientos | M7: 50817240/ 33355710 | N7: 50 | O7: 50 | P7: 50 | Q7: 50 | R7: 50 | S7: 50 | T7: 50 | U7: 50 | V7: 50 | W7: 50 | Z7: =SUM(N7:Y7) -> 500
A8: 1 | B8: Rodas Villeda | C8: Rodrigo Alexander | D8: =TRUNC((TODAY()-E8)/365) -> 18 | E8: 38998 | H8: 600 | L8: Ingrid Dinora Cifuentes Cruz | M8: 3575 9655 | Z8: =SUM(N8:Y8) -> 0
A9: 1 | B9: Velásquez Cano | C9: Sharon Dayan | D9: =TRUNC((TODAY()-E9)/365) -> 17 | E9: 39413 | G9: 50 | H9: 600 | K9: 40 | L9: Lesly Saydett Cano | M9: 44589744 | Z9: =SUM(N9:Y9) -> 0
A10: =SUM(A5:A9) -> 5 | H10: =SUM(H5:H9) -> 4150 | I10: =SUM(I5:I9) -> 0 | Z10: =SUM(Z5:Z9) -> 550
A25: 21
A26: 22
A27: 23
A28: 24
A29: 25

Sheet RESUMEN
A2: INSCRIPCIONES-Resumen de pagos y pendiente de pago
A3: AÑO ESCOLAR 2025
A4: Grado | B4: Inscritos | C4: % Beca | D4: Aporte | E4: Aporte pendiente
A5: 1° Básico | B5: ='1ERO. BÁSICO'!A32 -> 27 | D5: ='1ERO. BÁSICO'!H32 -> 15950 | E5: ='1ERO. BÁSICO'!I32 -> 900
A6: 2° Básico | B6: ='2DO. BÁSICO'!A32 -> 27 | D6: ='2DO. BÁSICO'!H32 -> 16600 | E6: ='2DO. BÁSICO'!I32 -> 400
A7: 3° Básico | B7: ='3ERO. BÁSICO'!A26 -> 18 | D7: ='3ERO. BÁSICO'!H26 -> 10950 | E7: ='3ERO. BÁSICO'!I26 -> 2650
A8: 4° Bachillerato | B8: ='4TO. BACHILLERATO'!A19 -> 12 | D8: ='4TO. BACHILLERATO'!H19 -> 8600 | E8: ='4TO. BACHILLERATO'!I19 -> 600
A9: 5° Bachillerato | B9: ='5TO. BACHILLERATO'!A10 -> 5 | D9: ='5TO. BACHILLERATO'!H10 -> 4150 | E9: ='5TO. BACHILLERATO'!I10 -> 0
A10: Total | B10: =SUM(B5:B9) -> 89 | D10: =SUM(D5:D9) -> 56250 | E10: =SUM(E5:E9) -> 4550

Sheet Para administración
B2: RESUMEN GENERAL DE INSCRIPCIONES
A3: PRIMERO BÁSICO
A4: N° | B4: Nombre | C4: Apellidos | D4: Inscripción IGER | E4: 1era. Entrega 25.11 | F4: 2da. Entrega 02.12 | G4: 3° Entrega 09.12 | H4: 4 entrega | I4: 5° Entrega | J4: 6ta. Entrega | K4: 7ma. Entrega | L4: 8° Entrega | M4: 9° Entrega | N4: Total | O4: G. Admon | P4: Mensualidad
A5: 1 | B5: Álvarez de la Cruz | C5: Astrid Dayana | D5: 525 | H5: 300 | J5: 300 | N5: =SUM(E5:J5) -> 600 | O5: =N5-D5 -> 75
A6: 1 | B6: Amaya Pérez | C6: Ana Camila Suceth | D6: 525 | J6: 600 | N6: =SUM(E6:J6) -> 600 | O6: =N6-D6 -> 75
A7: 1 | B7: Armis | C7: Ángel Manuel | D7: 525 | F7: 600 | I7: 200 | N7: =SUM(E7:J7) -> 800 | O7: =N7-D7 -> 275 | P7: 200
A8: 1 | B8: Batres Echeverria | C8: Marco Antonio | D8: 525 | E8: 600 | N8: =SUM(E8:J8) -> 600 | O8: =N8-D8 -> 75
A9: 1 | B9: Bonilla | C9: Jhorgeysil Ayleen | D9: 525 | E9: 200 | G9: 100 | N9: =SUM(E9:J9) -> 300 | O9: =N9-D9 -> -225
A10: 1 | B10: Flores Soyoy | C10: Angie Delyanne | D10: 525 | E10: 300 | H10: 200 | L10: 100 | N10: =SUM(E10:L10) -> 600 | O10: =N10-D10 -> 75
A11: 1 | B11: Gómez Rodríguez | C11: Abi Michelle | D11: 525 | E11: 65 | G11: 300 | J11: 335 | N11: =SUM(E11:J11) -> 700 | O11: =N11-D11 -> 175 | P11: 100
A12: 1 | B12: González Ordoñez | C12: Prisly Adairiz | D12: 525 | G12: 600 | N12: =SUM(E12:J12) -> 600 | O12: =N12-D12 -> 75
A13: 1 | B13: González Sí | C13: Hamilthon Esau | D13: 525 | E13: 200 | G13: 200 | J13: 200 | N13: =SUM(E13:J13) -> 600 | O13: =N13-D13 -> 75
A14: 1 | B14: Jiménez Soyoy | C14: Sharon Alejandra | D14: 525 | G14: 300 | M14: 300 | N14: =SUM(E14:J14) -> 300 | O14: =N14-D14 -> -225
A15: 1 | B15: Juárez Escalante | C15: Lisandro Saúl | D15: 525 | G15: 300 | I15: 350 | N15: =SUM(E15:J15) -> 650 | O15: =N15-D15 -> 125 | P15: 50
A16: 1 | B16: Macario Vicente | C16: Rosa María | D16: 525 | H16: 25 | J16: 575 | N16: =SUM(E16:J16) -> 600 | O16: =N16-D16 -> 75
A17: 1 | B17: Montes Arreola | C17: Austin Daniel | D17: 525 | E17: 600 | N17: =SUM(E17:J17) -> 600 | O17: =N17-D17 -> 75
A18: 1 | B18: Natareno Toc | C18: Jeffrey Mateo | D18: 525 | G18: 600 | N18: =SUM(E18:J18) -> 600 | O18: =N18-D18 -> 75
A19: 1 | B19: Patzán Hernández | C19: Mario Martín | D19: 525 | E19: 300 | N19: =SUM(E19:J19) -> 300 | O19: =N19-D19 -> -225
A20: 1 | B20: Rodas Zurdo | C20: Diego Andreé | D20: 525 | E20: 100 | F20: 500 | N20: =SUM(E20:J20) -> 600 | O20: =N20-D20 -> 75
A21: 1 | B21: Romero Méndez | C21: Katherine Mariana | D21: 525 | E21: 300 | F21: 300 | N21: =SUM(E21:J21) -> 600 | O21: =N21-D21 -> 75
A22: 1 | B22: Roquel Caniche | C22: Edwin David | D22: 525 | E22: 300 | J22: 350 | N22: =SUM(E22:J22) -> 650 | O22: =N22-D22 -> 125 | P22: 50
A23: 1 | B23: Soc Grande | C23: Norman Isaac | D23: 525 | I23: 1100 | N23: =SUM(E23:J23) -> 1100 | O23: =N23-D23 -> 575 | P23: 500
A24: 1 | B24: Váldez Urbina | C24: Jennyfer Ximena | D24: 525 | E24: 300 | N24: =SUM(E24:J24) -> 300 | O24: =N24-D24 -> -225
A25: 1 | B25: Rivas Velásquez | C25: Martina Fátima | D25: 525 | E25: 300 | J25: 300 | N25: =SUM(E25:J25) -> 600 | O25: =N25-D25 -> 75
A26: 1 | B26: Contreras Corea | C26: Alberth de Jesús | D26: 525 | J26: 600 | N26: =SUM(E26:J26) -> 600 | O26: =N26-D26 -> 75
A27: 1 | B27: Ismalé Pérez | C27: Antoni Vinicio | D27: 525 | E27: 600 | N27: =SUM(E27:J27) -> 600 | O27: =N27-D27 -> 75
A28: 1 | B28: Simón Peren | C28: Candy Fabiola Odeth | D28: 525 | G28: 650 | N28: =SUM(E28:J28) -> 650 | O28: =N28-D28 -> 125 | P28: 50
A29: 1 | B29: Molina Case | C29: Jhoshua Gamaliel | D29: 525 | I29: 300 | L29: 300 | N29: =SUM(E29:L29) -> 600 | O29: =N29-D29 -> 75
A30: 1 | B30: Benito Pérez | C30: Kiara Julissa Leilany | D30: 525 | H30: 300 | N30: =SUM(E30:J30) -> 300 | O30: =N30-D30 -> -225
A31: 1 | B31: Mateo Sapón | C31: Tomás Santiago | D31: 525 | K31: 600 | N31: =SUM(E31:K31) -> 600 | O31: =N31-D31 -> 75
A32: =SUM(A5:A31) -> 27 | D32: =SUM(D5:D31) -> 14175 | E32: =SUM(E5:E27) -> 4165 | F32: =SUM(F5:F27) -> 1400 | G32: =SUM(G5:G29) -> 3050 | H32: =SUM(H5:H30) -> 825 | I32: =SUM(I5:I30) -> 1950 | J32: =SUM(J5:J30) -> 3260 | K32: =SUM(K5:K31) -> 600 | L32: =SUM(L5:L31) -> 400 | M32: =SUM(M5:M31) -> 300 | N32: =SUM(N5:N31) -> 15650 | P32: =SUM(P5:P31) -> 950
A51: SEGUNDO BÁSICO
A53: N° | B53: Nombre | C53: Apellidos | D53: IGER | E53: 1era. Entrega 25.11 | F53: 2da Entrega 02.12 | G53: 3° Entrega 09.12 | H53: 4 Entrega | I53: 5ta. Entrega | J53: 6ta. Entrega | N53: Total | O53: G. Admon | P53: Mensualidad
A54: 1 | B54: Carrera Lobos | C54: Mia Scarlet Susana | D54: 525 | G54: 600 | N54: =SUM(E54:J54) -> 600 | O54: =N54-D54 -> 75
A55: 1 | B55: Chocoj Rodríguez | C55: Candy Mishelle | D55: 525 | E55: 300 | J55: 300 | N55: =SUM(E55:J55) -> 600 | O55: =N55-D55 -> 75
A56: 1 | B56: Fernández Raymundo | C56: Daniela Jimena | D56: 525 | F56: 500 | N56: =SUM(E56:J56) -> 500 | O56: =N56-D56 -> -25
A57: 1 | B57: Hernández Mendoza | C57: Adam Carlos Enrique | D57: 525 | J57: 700 | N57: =SUM(E57:J57) -> 700 | O57: =N57-D57 -> 175 | P57: 100
A58: 1 | B58: Hernández Vargas | C58: Kareli Nicoll | D58: 525 | F58: 600 | N58: =SUM(E58:J58) -> 600 | O58: =N58-D58 -> 75
A59: 1 | B59: Higueros Burrión | C59: Alexandra Yanet | D59: 525 | L59: 600 | N59: =SUM(E59:L59) -> 600 | O59: =N59-D59 -> 75
A60: 1 | B60: Marroquín Orantes | C60: Scarlett Dajane | D60: 525 | J60: 800 | N60: =SUM(E60:J60) -> 800 | O60: =N60-D60 -> 275 | P60: 200
...

Sheet Inscripción 2024
A1: LISTADO DE ESTUDIANTES PARA INSCRIBIR EN DICIEMBRE DE 2024
A3: PRIMERO BÁSICO. Q.525.00
A5: N° | B5: Nombre | C5: Apellidos | D5: Fecha de nacimiento
A6: 1 | B6: Álvarez de la Cruz | C6: Astrid Dayana | D6: 40909
A7: 2 | B7: Armis | C7: Ángel Manuel | D7: 40591
A8: 3 | B8: Batres Echeverria | C8: Marco Antonio | D8: 40766
A9: 4 | B9: Bonilla | C9: Jhorgeysil Ayleen | D9: 41068
A10: 5 | B10: Flores Soyoy | C10: Angie Delyanne | D10: 41048
A11: 6 | B11: Gómez Rodríguez | C11: Abi Michelle | D11: 41145
A12: 7 | B12: González Ordoñez | C12: Prisly Adairiz | D12: 40624
A13: 8 | B13: González Sí | C13: Hamilthon Esaú | D13: 40845
A14: 9 | B14: Jiménez Soyoy | C14: Sharon Alejandra | D14: 40451
A15: 10 | B15: Juárez Escalante | C15: Lisandro Saúl | D15: 41011
A16: 11 | B16: Montes Arreola | C16: Austin Daniel | D16: 41018
A17: 12 | B17: Natareno Toc | C17: Jeffrey Mateo | D17: 40784
... A26: 21 | B26: Benito Pérez | C26: Kiara Julissa Leilany | D26: 40528
A31: SEGUNDO BÁSICO
A33: N° | B33: Nombre | C33: Apellidos | D33: Fecha de nacimiento
A34: 1 | B34: Carrera Lobos | C34: Mia Scarlet Susana | D34: 40583
A35: 2 | B35: Chocoj Rodríguez | C35: Candy Mishelle | D35: 40738
A36: 3 | B36: Fernández Raymundo | C36: Daniela Jimena | D36: 39569
A37: 4 | B37: Hernández Vargas | C37: Karely Nicole | D37: 40604
A38: 5 | B38: Higueros Burrión | C38: Alexandra Anahí Yanet | D38: 39256
A39: 6 | B39: Martin Ajiatáz | C39: Melany Anahí | D39: 39345
A40: 7 | B40: Meletz Carrera | C40: Kristen Nicol | D40: 40406
A41: 8 | B41: Méndez Ijchajchal | C41: Jeremy Alexis | D41: 40693
A42: 9 | B42: Morales Agustín | C42: Ilbia Rosalia | D42: 40478
A43: 10 | B43: Ordoñez Zurdo | C43: Pedro Josué | D43: 39855
A44: 11 | B44: Ordoñez Zurdo | C44: Julio Alejandro Jeremiah | D44: 40004
A45: 12 | B45: Patzan Díaz | C45: Sherlin Esmeralda | D45: 40615
... A50: 17 | B50: Toledo Chiquitó | C50: Kristofer Augusto | D50: 39975
A51: 18 | B51: Tzul Quiñónez | C51: Londy María | D51: 26-012009
A52: 19 | B52: Morataya Patzán | C52: Estefany Paola | D52: 40718
A53: 20 | B53: Ozuna Barillas | C53: Ghylaine Cristina | D53: 40269
A60: TERCERO BÁSICO
A61: N° | B61: Nombre | C61: Apellidos | D61: Fecha de nacimiento
A62: 1 | B62: Chaman | C62: Jessica Paola | D62: 40002
A63: 2 | B63: Cuc Gonzáles | C63: Naomi Susana | D63: 40135
A64: 3 | B64: Figueroa Martínez | C64: Eddy Randolfo | D64: 40030
A65: 4 | B65: Jocón Barillas | C65: Emily Julissa | D65: 40041
...

Sheet INSCRIPCIÓN ENERO
B2: RESUMEN GENERAL DE INSCRIPCIONES
A3: PRIMERO BÁSICO
A4: N° | B4: Nombre | C4: Apellidos | D4: IGER
A5: 1 | B5: Amaya Pérez | C5: Ana Camila Suceth | D5: 525
A6: 1 | B6: Macario Vicente | C6: Rosa María | D6: 525
A7: 1 | B7: Soc Grande | C7: Norman Isaac | D7: 525
A8: 1 | B8: Contreras Corea | C8: Alberth de Jesús | D8: 525
A9: 1 | B9: Simón Peren | C9: Candy Fabiola Odeth | D9: 525
A10: 1 | B10: Molina Case | C10: Jhoshua Gamaliel | D10: 525
A11: =SUM(A5:A10) -> 6 | D11: =SUM(D5:D10) -> 3150
A14: SEGUNDO BÁSICO
A16: N° | B16: Nombre | C16: Apellidos | D16: IGER
A17: 1 | B17: Hernández Mendoza | C17: Adam Carlos Enrique | D17: 525
A18: 1 | B18: Marroquín Orantes | C18: Scarlett Dajane | D18: 525
A19: 1 | B19: Solis Salguero | C19: Iñaki Lorenzo Antonio | D19: 525
A20: 1 | B20: Yoque Domingo | C20: Erick Andrés | D20: 525
A21: 1 | B21: Contreras Corea | C21: Sharóm Solansh Gabriela | D21: 525
A22: 1 | B22: Fernández Reyes | C22: William Jesús | D22: 525
A23: 1 | B23: Gutiérrez Salazar | C23: Ligia Virginia | D23: 525
A24: 1 | B24: Méndez Jacobo | C24: Catherine Helizabeth
A25: =SUM(A17:A24) -> 8 | D25: =SUM(D17:D24) -> 3675
A28: TERCERO BÁSICO
A29: N° | B29: Nombre | C29: Apellidos | D29: IGER
A30: 1 | B30: Ochoa Quisquinai | C30: Angelín Daniela | D30: 525
A31: 1 | B31: Patzán Morales | C31: Cristian Rodolfo | D31: 525
A32: 1 | B32: Quisquina Locón | C32: Axel Eduardo | D32: 525
A33: 1 | B33: Sicay Pérez | C33: Mayda Nicol | D33: 525
A34: 1 | B34: Molina Case | C34: Maryury Daniela | D34: 525
A35: =SUM(A30:A34) -> 5 | D35: =SUM(D30:D34) -> 2625
A48: CUARTO BACHILLERATO
A49: N° | B49: Nombre | C49: Apellidos | D49: IGER
A50: 1 | B50: Sánchez Pérez | C50: Cristian Manuel | D50: 575
A51: 1 | B51: Ponce Suchite | C51: Carmen Sarahi | D51: 575
A52: 1 | B52: Velásquez Raxón | C52: Franklin Ricardo | D52: 575
A53: 1 | B53: González Yoc | C53: Dulce María José | D53: 575
A54: =SUM(A50:A53) -> 4 | D54: =SUM(D50:D53) -> 2300
A58: QUINTO BACHILLERATO
A59: N° | B59: Nombre | C59: Apellidos
A60: 1 | B60: Barrios Cuyun | C60: Jaqueline Paola | D60: 550
A61: 1 | B61: Gutiérrez Gálvez | C61: Francisco Jesús | D61: 550
...
